<?xml version="1.0" ?>
<robot name="toddlerbot_2xm_gripper">
  <mujoco>
    <compiler strippath="false" balanceinertia="true" discardvisual="false"/>
  </mujoco>
  <link name="world">
    <inertial>
      <origin xyz="0.0 0.0 0.0" rpy="0.0 0.0 0.0"/>
      <mass value="0.0"/>
      <inertia ixx="0.0" iyy="0.0" izz="0.0" ixy="0" ixz="0" iyz="0"/>
    </inertial>
  </link>
  <link name="torso">
    <inertial>
      <origin xyz="-0.0194013 -0.00385148 0.0614411" rpy="-0.696046 0.0702126 0.11645"/>
      <mass value="1.27503"/>
      <inertia ixx="0.0034129583257935087" iyy="0.002742169867460665" izz="0.0026376418067458225" ixy="0" ixz="0" iyz="0"/>
    </inertial>
    <visual name="torso_visual">
      <origin xyz="-0.0194013 -0.00385148 0.0614411" rpy="0.0 0.0 0.0"/>
      <geometry>
        <mesh filename="assets/torso_visual.stl" scale="1.0 1.0 1.0"/>
      </geometry>
      <material name="torso_visual_material"/>
    </visual>
    <collision name="torso_collision_0">
      <origin xyz="-0.025508 0.0 0.06" rpy="0.0 0.0 0.0"/>
      <geometry>
        <box type="box" size="0.09 0.13 0.12"/>
      </geometry>
    </collision>
    <collision name="torso_collision_1">
      <origin xyz="-0.093008 0.0 0.01425" rpy="0.0 0.0 0.0"/>
      <geometry>
        <box type="box" size="0.045 0.0285 0.0285"/>
      </geometry>
    </collision>
  </link>
  <link name="torso_freejoint_body">
    <inertial>
      <origin xyz="0.0 0.0 0.0" rpy="0.0 0.0 0.0"/>
      <mass value="0.001"/>
      <inertia ixx="1e-09" iyy="1e-09" izz="1e-09" ixy="0" ixz="0" iyz="0"/>
    </inertial>
  </link>
  <joint type="floating" name="torso_freejoint">
    <parent link="world"/>
    <child link="torso_freejoint_body"/>
    <origin xyz="0.0 0.0 0.315053" rpy="0.0 0.0 0.0"/>
    <limit lower="-999999" upper="999999" effort="1000" velocity="1000"/>
  </joint>
  <joint type="fixed" name="torso_freejoint_offset">
    <parent link="torso_freejoint_body"/>
    <child link="torso"/>
    <origin xyz="0.0 0.0 0.0" rpy="0.0 0.0 0.0"/>
  </joint>
  <link name="neck_yaw_gear_drive">
    <inertial>
      <origin xyz="8.2581e-17 1.36534e-15 0.0033841" rpy="1.5708 -1.5708 0.0"/>
      <mass value="0.003"/>
      <inertia ixx="1.55295e-07" iyy="8.71388e-08" izz="8.71388e-08" ixy="0" ixz="0" iyz="0"/>
    </inertial>
    <visual name="neck_yaw_gear_drive_visual">
      <origin xyz="8.38906e-17 1.36534e-15 0.0033841" rpy="0.0 0.0 0.0"/>
      <geometry>
        <mesh filename="assets/neck_yaw_gear_drive_visual.stl" scale="1.0 1.0 1.0"/>
      </geometry>
      <material name="neck_yaw_gear_drive_visual_material"/>
    </visual>
  </link>
  <link name="neck_yaw_drive_body">
    <inertial>
      <origin xyz="0.0 0.0 0.0" rpy="0.0 0.0 0.0"/>
      <mass value="0.001"/>
      <inertia ixx="1e-09" iyy="1e-09" izz="1e-09" ixy="0" ixz="0" iyz="0"/>
    </inertial>
  </link>
  <joint type="fixed" name="neck_yaw_drive">
    <parent link="torso"/>
    <child link="neck_yaw_drive_body"/>
    <origin xyz="-0.0215079 1.21496e-14 0.119" rpy="0.0 0.0 0.0"/>
  </joint>
  <joint type="fixed" name="neck_yaw_drive_offset">
    <parent link="neck_yaw_drive_body"/>
    <child link="neck_yaw_gear_drive"/>
    <origin xyz="0.0 0.0 0.0" rpy="0.0 0.0 0.0"/>
  </joint>
  <link name="neck_yaw_link">
    <inertial>
      <origin xyz="-3.4067e-06 -1.86e-09 0.00821562" rpy="-0.0150909 0.0 1.5708"/>
      <mass value="0.006"/>
      <inertia ixx="6.2064e-07" iyy="4.777318598148802e-07" izz="3.2903914018512005e-07" ixy="0" ixz="0" iyz="0"/>
    </inertial>
    <visual name="neck_yaw_link_visual">
      <origin xyz="-3.4067e-06 -1.86e-09 0.00821562" rpy="-6.8060000000000006e-18 1.11022e-15 2.23308e-16"/>
      <geometry>
        <mesh filename="assets/neck_yaw_link_visual.stl" scale="1.0 1.0 1.0"/>
      </geometry>
      <material name="neck_yaw_link_visual_material"/>
    </visual>
  </link>
  <link name="neck_yaw_driven_body">
    <inertial>
      <origin xyz="0.0 0.0 0.0" rpy="0.0 0.0 0.0"/>
      <mass value="0.001"/>
      <inertia ixx="1e-09" iyy="1e-09" izz="1e-09" ixy="0" ixz="0" iyz="0"/>
    </inertial>
  </link>
  <joint type="revolute" name="neck_yaw_driven">
    <parent link="torso"/>
    <child link="neck_yaw_driven_body"/>
    <origin xyz="-0.00050787 -1.1277e-19 0.124" rpy="0.0 0.0 0.0"/>
    <axis xyz="0.0 0.0 1.0"/>
    <limit lower="-2.6179938779914944" upper="2.6179938779914944" effort="100" velocity="100"/>
  </joint>
  <joint type="fixed" name="neck_yaw_driven_offset">
    <parent link="neck_yaw_driven_body"/>
    <child link="neck_yaw_link"/>
    <origin xyz="0.0 0.0 0.0" rpy="0.0 0.0 0.0"/>
  </joint>
  <link name="head">
    <inertial>
      <origin xyz="-0.0104852 0.00111009 0.0447856" rpy="-0.523779 0.0532002 1.54487"/>
      <mass value="0.143321"/>
      <inertia ixx="0.00012202103620349928" iyy="0.00011484347868761217" izz="9.015538510888831e-05" ixy="0" ixz="0" iyz="0"/>
    </inertial>
    <visual name="head_visual">
      <origin xyz="-0.0104852 0.00111009 0.0447856" rpy="4.4409e-16 8.88178e-16 1.41626e-16"/>
      <geometry>
        <mesh filename="assets/head_visual.stl" scale="1.0 1.0 1.0"/>
      </geometry>
      <material name="head_visual_material"/>
    </visual>
    <collision name="head_collision">
      <origin xyz="-0.0105 -0.0035 0.046416" rpy="4.4409e-16 8.88178e-16 1.41626e-16"/>
      <geometry>
        <box type="box" size="0.07 0.084 0.06"/>
      </geometry>
    </collision>
  </link>
  <link name="neck_pitch_body">
    <inertial>
      <origin xyz="0.0 0.0 0.0" rpy="0.0 0.0 0.0"/>
      <mass value="0.001"/>
      <inertia ixx="1e-09" iyy="1e-09" izz="1e-09" ixy="0" ixz="0" iyz="0"/>
    </inertial>
  </link>
  <joint type="revolute" name="neck_pitch">
    <parent link="neck_yaw_link"/>
    <child link="neck_pitch_body"/>
    <origin xyz="9.24195e-17 0.004 0.015" rpy="0.0 0.0 0.0"/>
    <axis xyz="0.0 1.0 0.0"/>
    <limit lower="-0.6108652381980295" upper="1.3962634015954494" effort="100" velocity="100"/>
  </joint>
  <joint type="fixed" name="neck_pitch_offset">
    <parent link="neck_pitch_body"/>
    <child link="head"/>
    <origin xyz="0.0 0.0 0.0" rpy="0.0 0.0 0.0"/>
  </joint>
  <link name="neck_pitch_plate">
    <inertial>
      <origin xyz="-1.80633e-16 -0.00282818 6.9349e-16" rpy="1.83622 -1.5708 0.0"/>
      <mass value="0.002"/>
      <inertia ixx="1.08464e-07" iyy="6.126017302052663e-08" izz="5.619012697947335e-08" ixy="0" ixz="0" iyz="0"/>
    </inertial>
    <visual name="neck_pitch_plate_visual">
      <origin xyz="-1.82311e-16 -0.00282818 6.90937e-16" rpy="-2.4425e-13 8.88178e-16 2.11838e-16"/>
      <geometry>
        <mesh filename="assets/neck_pitch_plate_visual.stl" scale="1.0 1.0 1.0"/>
      </geometry>
      <material name="neck_pitch_plate_visual_material"/>
    </visual>
  </link>
  <link name="neck_pitch_act_body">
    <inertial>
      <origin xyz="0.0 0.0 0.0" rpy="0.0 0.0 0.0"/>
      <mass value="0.001"/>
      <inertia ixx="1e-09" iyy="1e-09" izz="1e-09" ixy="0" ixz="0" iyz="0"/>
    </inertial>
  </link>
  <joint type="fixed" name="neck_pitch_act">
    <parent link="head"/>
    <child link="neck_pitch_act_body"/>
    <origin xyz="-0.027 -0.0025 0.0326157" rpy="0.0 0.0 0.0"/>
  </joint>
  <joint type="fixed" name="neck_pitch_act_offset">
    <parent link="neck_pitch_act_body"/>
    <child link="neck_pitch_plate"/>
    <origin xyz="0.0 0.0 0.0" rpy="0.0 0.0 0.0"/>
  </joint>
  <link name="neck_rod">
    <inertial>
      <origin xyz="0.0135129 -0.00159086 -0.0162914" rpy="1.5708 -1.57068 -0.000851233"/>
      <mass value="0.00297389"/>
      <inertia ixx="9.687790001859902e-07" iyy="9.560376800415566e-07" izz="1.727231977245297e-08" ixy="0" ixz="0" iyz="0"/>
    </inertial>
    <visual name="neck_rod_visual">
      <origin xyz="0.0135129 -0.00159086 -0.0162914" rpy="3.55271e-15 4.6406e-07 0.0"/>
      <geometry>
        <mesh filename="assets/neck_rod_visual.stl" scale="1.0 1.0 1.0"/>
      </geometry>
      <material name="neck_rod_visual_material"/>
    </visual>
  </link>
  <link name="neck_pitch_front_body">
    <inertial>
      <origin xyz="0.0 0.0 0.0" rpy="0.0 0.0 0.0"/>
      <mass value="0.001"/>
      <inertia ixx="1e-09" iyy="1e-09" izz="1e-09" ixy="0" ixz="0" iyz="0"/>
    </inertial>
  </link>
  <joint type="fixed" name="neck_pitch_front">
    <parent link="neck_pitch_plate"/>
    <child link="neck_pitch_front_body"/>
    <origin xyz="0.00723736 -0.0055 0.0019674" rpy="0.0 0.0 0.0"/>
  </joint>
  <joint type="fixed" name="neck_pitch_front_offset">
    <parent link="neck_pitch_front_body"/>
    <child link="neck_rod"/>
    <origin xyz="0.0 0.0 0.0" rpy="0.0 0.0 0.0"/>
  </joint>
  <link name="neck_rod_2">
    <inertial>
      <origin xyz="0.0135222 -0.00159086 -0.0162731" rpy="-1.5708 -1.57064 3.14049"/>
      <mass value="0.00297389"/>
      <inertia ixx="9.677590003106885e-07" iyy="9.550161316836337e-07" izz="1.7273468005677697e-08" ixy="0" ixz="0" iyz="0"/>
    </inertial>
    <visual name="neck_rod_2_visual">
      <origin xyz="0.0135222 -0.00159086 -0.0162731" rpy="-2.45012e-13 8.4516e-07 -6.50591e-14"/>
      <geometry>
        <mesh filename="assets/neck_rod_2_visual.stl" scale="1.0 1.0 1.0"/>
      </geometry>
      <material name="neck_rod_2_visual_material"/>
    </visual>
  </link>
  <link name="neck_pitch_back_body">
    <inertial>
      <origin xyz="0.0 0.0 0.0" rpy="0.0 0.0 0.0"/>
      <mass value="0.001"/>
      <inertia ixx="1e-09" iyy="1e-09" izz="1e-09" ixy="0" ixz="0" iyz="0"/>
    </inertial>
  </link>
  <joint type="fixed" name="neck_pitch_back">
    <parent link="neck_pitch_plate"/>
    <child link="neck_pitch_back_body"/>
    <origin xyz="-0.00723736 -0.0055 -0.0019674" rpy="0.0 0.0 0.0"/>
  </joint>
  <joint type="fixed" name="neck_pitch_back_offset">
    <parent link="neck_pitch_back_body"/>
    <child link="neck_rod_2"/>
    <origin xyz="0.0 0.0 0.0" rpy="0.0 0.0 0.0"/>
  </joint>
  <link name="waist_gears">
    <inertial>
      <origin xyz="-2.81849e-10 1.55293e-09 -0.0129916" rpy="1.5708 3.81109e-06 1.5708"/>
      <mass value="0.0371617"/>
      <inertia ixx="1.1906300000004848e-05" iyy="1.1572599999995153e-05" izz="2.6567e-06" ixy="0" ixz="0" iyz="0"/>
    </inertial>
    <visual name="waist_gears_visual">
      <origin xyz="-2.81849e-10 1.55293e-09 -0.0129916" rpy="-4.6604e-17 0.0 -1.2326000000000002e-32"/>
      <geometry>
        <mesh filename="assets/waist_gears_visual.stl" scale="1.0 1.0 1.0"/>
      </geometry>
      <material name="waist_gears_visual_material"/>
    </visual>
  </link>
  <link name="waist_yaw_body">
    <inertial>
      <origin xyz="0.0 0.0 0.0" rpy="0.0 0.0 0.0"/>
      <mass value="0.001"/>
      <inertia ixx="1e-09" iyy="1e-09" izz="1e-09" ixy="0" ixz="0" iyz="0"/>
    </inertial>
  </link>
  <joint type="revolute" name="waist_yaw">
    <parent link="torso"/>
    <child link="waist_yaw_body"/>
    <origin xyz="-0.0165079 -1.92151e-17 -0.00248651" rpy="0.0 0.0 0.0"/>
    <axis xyz="0.0 0.0 1.0"/>
    <limit lower="-1.570796326794878" upper="1.5707963267949152" effort="100" velocity="100"/>
  </joint>
  <joint type="fixed" name="waist_yaw_offset">
    <parent link="waist_yaw_body"/>
    <child link="waist_gears"/>
    <origin xyz="0.0 0.0 0.0" rpy="0.0 0.0 0.0"/>
  </joint>
  <link name="pelvis_link">
    <inertial>
      <origin xyz="-0.0231545 1.60597e-15 -0.0260806" rpy="1.57054 -0.0185878 1.5708"/>
      <mass value="0.1052"/>
      <inertia ixx="9.14431991849157e-05" iyy="6.742020227196802e-05" izz="4.570519854311625e-05" ixy="0" ixz="0" iyz="0"/>
    </inertial>
    <visual name="pelvis_link_visual">
      <origin xyz="-0.0231545 1.60597e-15 -0.0260806" rpy="-8.88178e-16 -4.44089e-16 -2.87548e-14"/>
      <geometry>
        <mesh filename="assets/pelvis_link_visual.stl" scale="1.0 1.0 1.0"/>
      </geometry>
      <material name="pelvis_link_visual_material"/>
    </visual>
    <collision name="pelvis_link_collision">
      <origin xyz="-0.02275 6.22778e-16 -0.035346" rpy="-8.88178e-16 -4.44089e-16 -2.87548e-14"/>
      <geometry>
        <box type="box" size="0.07 0.12 0.044338"/>
      </geometry>
    </collision>
  </link>
  <link name="waist_roll_body">
    <inertial>
      <origin xyz="0.0 0.0 0.0" rpy="0.0 0.0 0.0"/>
      <mass value="0.001"/>
      <inertia ixx="1e-09" iyy="1e-09" izz="1e-09" ixy="0" ixz="0" iyz="0"/>
    </inertial>
  </link>
  <joint type="revolute" name="waist_roll">
    <parent link="waist_gears"/>
    <child link="waist_roll_body"/>
    <origin xyz="0.0230079 2.89995e-16 -0.014" rpy="0.0 0.0 0.0"/>
    <axis xyz="1.0 0.0 0.0"/>
    <limit lower="-0.5235987755983015" upper="0.5235987755982962" effort="100" velocity="100"/>
  </joint>
  <joint type="fixed" name="waist_roll_offset">
    <parent link="waist_roll_body"/>
    <child link="pelvis_link"/>
    <origin xyz="0.0 0.0 0.0" rpy="0.0 0.0 0.0"/>
  </joint>
  <link name="waist_gear_drive">
    <inertial>
      <origin xyz="3.70003e-10 -6.58783e-10 0.00671824" rpy="1.5708 -1.5708 0.0"/>
      <mass value="0.002"/>
      <inertia ixx="3.95436e-08" iyy="3.70258e-08" izz="3.70258e-08" ixy="0" ixz="0" iyz="0"/>
    </inertial>
    <visual name="waist_gear_drive_visual">
      <origin xyz="3.70003e-10 -6.58783e-10 0.00671824" rpy="-3.55271e-15 -8.88178e-16 -8.17124e-14"/>
      <geometry>
        <mesh filename="assets/waist_gear_drive_visual.stl" scale="1.0 1.0 1.0"/>
      </geometry>
      <material name="waist_gear_drive_visual_material"/>
    </visual>
  </link>
  <link name="waist_act_1_body">
    <inertial>
      <origin xyz="0.0 0.0 0.0" rpy="0.0 0.0 0.0"/>
      <mass value="0.001"/>
      <inertia ixx="1e-09" iyy="1e-09" izz="1e-09" ixy="0" ixz="0" iyz="0"/>
    </inertial>
  </link>
  <joint type="fixed" name="waist_act_1">
    <parent link="pelvis_link"/>
    <child link="waist_act_1_body"/>
    <origin xyz="-0.01275 -1.71841e-16 -0.0196" rpy="0.0 0.0 0.0"/>
  </joint>
  <joint type="fixed" name="waist_act_1_offset">
    <parent link="waist_act_1_body"/>
    <child link="waist_gear_drive"/>
    <origin xyz="0.0 0.0 0.0" rpy="0.0 0.0 0.0"/>
  </joint>
  <link name="waist_gear_drive_2">
    <inertial>
      <origin xyz="3.70003e-10 -6.58783e-10 0.00671824" rpy="1.5708 -1.5708 0.0"/>
      <mass value="0.002"/>
      <inertia ixx="3.95436e-08" iyy="3.70258e-08" izz="3.70258e-08" ixy="0" ixz="0" iyz="0"/>
    </inertial>
    <visual name="waist_gear_drive_2_visual">
      <origin xyz="3.70003e-10 -6.58783e-10 0.00671824" rpy="-3.55271e-15 -2.22045e-15 -6.30607e-14"/>
      <geometry>
        <mesh filename="assets/waist_gear_drive_2_visual.stl" scale="1.0 1.0 1.0"/>
      </geometry>
      <material name="waist_gear_drive_2_visual_material"/>
    </visual>
  </link>
  <link name="waist_act_2_body">
    <inertial>
      <origin xyz="0.0 0.0 0.0" rpy="0.0 0.0 0.0"/>
      <mass value="0.001"/>
      <inertia ixx="1e-09" iyy="1e-09" izz="1e-09" ixy="0" ixz="0" iyz="0"/>
    </inertial>
  </link>
  <joint type="fixed" name="waist_act_2">
    <parent link="pelvis_link"/>
    <child link="waist_act_2_body"/>
    <origin xyz="-0.03275 1.40567e-16 -0.0196" rpy="0.0 0.0 0.0"/>
  </joint>
  <joint type="fixed" name="waist_act_2_offset">
    <parent link="waist_act_2_body"/>
    <child link="waist_gear_drive_2"/>
    <origin xyz="0.0 0.0 0.0" rpy="0.0 0.0 0.0"/>
  </joint>
  <link name="left_hip_pitch_link">
    <inertial>
      <origin xyz="-0.0203085 0.0188253 -0.0117862" rpy="1.57609 -0.00223222 1.56256"/>
      <mass value="0.188221"/>
      <inertia ixx="0.00013141757567323095" iyy="0.00011438871462386318" izz="5.023340970290577e-05" ixy="0" ixz="0" iyz="0"/>
    </inertial>
    <visual name="left_hip_pitch_link_visual">
      <origin xyz="-0.0203085 0.0188253 -0.0117862" rpy="-8.88178e-16 -4.44089e-16 -2.84217e-14"/>
      <geometry>
        <mesh filename="assets/left_hip_pitch_link_visual.stl" scale="1.0 1.0 1.0"/>
      </geometry>
      <material name="hip_pitch_link_visual_material"/>
    </visual>
    <collision name="left_hip_pitch_link_collision">
      <origin xyz="-0.01805 0.0168 -0.012" rpy="-8.88178e-16 -4.44089e-16 -2.84217e-14"/>
      <geometry>
        <box type="box" size="0.0859 0.0424 0.0465"/>
      </geometry>
    </collision>
  </link>
  <link name="left_hip_pitch_body">
    <inertial>
      <origin xyz="0.0 0.0 0.0" rpy="0.0 0.0 0.0"/>
      <mass value="0.001"/>
      <inertia ixx="1e-09" iyy="1e-09" izz="1e-09" ixy="0" ixz="0" iyz="0"/>
    </inertial>
  </link>
  <joint type="revolute" name="left_hip_pitch">
    <parent link="pelvis_link"/>
    <child link="left_hip_pitch_body"/>
    <origin xyz="-0.02275 0.018 -0.0481" rpy="0.0 0.0 0.0"/>
    <axis xyz="0.0 1.0 0.0"/>
    <limit lower="-2.356194490192225" upper="0.7853981633975682" effort="100" velocity="100"/>
  </joint>
  <joint type="fixed" name="left_hip_pitch_offset">
    <parent link="left_hip_pitch_body"/>
    <child link="left_hip_pitch_link"/>
    <origin xyz="0.0 0.0 0.0" rpy="0.0 0.0 0.0"/>
  </joint>
  <link name="left_hip_roll_link">
    <inertial>
      <origin xyz="0.0246449 -3.2234e-06 -0.0172318" rpy="0.0190768 -0.000313585 0.000387817"/>
      <mass value="0.022"/>
      <inertia ixx="9.951740710603494e-06" iyy="8.778876227225876e-06" izz="4.309323062170636e-06" ixy="0" ixz="0" iyz="0"/>
    </inertial>
    <visual name="left_hip_roll_link_visual">
      <origin xyz="0.0246449 -3.2234e-06 -0.0172318" rpy="-8.88178e-16 -4.44089e-16 -2.84217e-14"/>
      <geometry>
        <mesh filename="assets/left_hip_roll_link_visual.stl" scale="1.0 1.0 1.0"/>
      </geometry>
      <material name="hip_roll_link_visual_material"/>
    </visual>
  </link>
  <link name="left_hip_roll_body">
    <inertial>
      <origin xyz="0.0 0.0 0.0" rpy="0.0 0.0 0.0"/>
      <mass value="0.001"/>
      <inertia ixx="1e-09" iyy="1e-09" izz="1e-09" ixy="0" ixz="0" iyz="0"/>
    </inertial>
  </link>
  <joint type="revolute" name="left_hip_roll">
    <parent link="left_hip_pitch_link"/>
    <child link="left_hip_roll_body"/>
    <origin xyz="-0.023 0.019 -0.024" rpy="0.0 0.0 0.0"/>
    <axis xyz="1.0 0.0 0.0"/>
    <limit lower="-0.7853981633975363" upper="1.5707963267948084" effort="100" velocity="100"/>
  </joint>
  <joint type="fixed" name="left_hip_roll_offset">
    <parent link="left_hip_roll_body"/>
    <child link="left_hip_roll_link"/>
    <origin xyz="0.0 0.0 0.0" rpy="0.0 0.0 0.0"/>
  </joint>
  <link name="left_hip_yaw_link">
    <inertial>
      <origin xyz="-0.00967359 0.00117184 -0.0353305" rpy="-0.390642 -0.158031 0.0399734"/>
      <mass value="0.159688"/>
      <inertia ixx="7.953188969856982e-05" iyy="6.27698290206306e-05" izz="5.0352581280799714e-05" ixy="0" ixz="0" iyz="0"/>
    </inertial>
    <visual name="left_hip_yaw_link_visual">
      <origin xyz="-0.00967359 0.00117184 -0.0353305" rpy="-9.05942e-14 1.15463e-14 -2.88658e-14"/>
      <geometry>
        <mesh filename="assets/left_hip_yaw_link_visual.stl" scale="1.0 1.0 1.0"/>
      </geometry>
      <material name="hip_yaw_link_visual_material"/>
    </visual>
    <collision name="left_hip_yaw_link_collision">
      <origin xyz="-0.009525 0.000575004 -0.031475" rpy="-9.05942e-14 1.15463e-14 -2.88658e-14"/>
      <geometry>
        <box type="box" size="0.05905 0.04795 0.06295"/>
      </geometry>
    </collision>
  </link>
  <link name="left_hip_yaw_driven_body">
    <inertial>
      <origin xyz="0.0 0.0 0.0" rpy="0.0 0.0 0.0"/>
      <mass value="0.001"/>
      <inertia ixx="1e-09" iyy="1e-09" izz="1e-09" ixy="0" ixz="0" iyz="0"/>
    </inertial>
  </link>
  <joint type="revolute" name="left_hip_yaw_driven">
    <parent link="left_hip_roll_link"/>
    <child link="left_hip_yaw_driven_body"/>
    <origin xyz="0.023 -6.96693e-16 -0.033" rpy="0.0 0.0 0.0"/>
    <axis xyz="0.0 0.0 -1.0"/>
    <limit lower="-1.570796326794896" upper="1.5707963267948972" effort="100" velocity="100"/>
  </joint>
  <joint type="fixed" name="left_hip_yaw_driven_offset">
    <parent link="left_hip_yaw_driven_body"/>
    <child link="left_hip_yaw_link"/>
    <origin xyz="0.0 0.0 0.0" rpy="0.0 0.0 0.0"/>
  </joint>
  <link name="left_hip_yaw_gear_drive">
    <inertial>
      <origin xyz="8.70043e-17 -3.26845e-16 0.00175" rpy="1.5708 -1.5708 0.0"/>
      <mass value="0.001"/>
      <inertia ixx="4.7219e-08" iyy="2.46213e-08" izz="2.46213e-08" ixy="0" ixz="0" iyz="0"/>
    </inertial>
    <visual name="left_hip_yaw_gear_drive_visual">
      <origin xyz="8.6489e-17 -3.24943e-16 0.00175" rpy="-9.07314e-14 1.15463e-14 -1.31386e-13"/>
      <geometry>
        <mesh filename="assets/left_hip_yaw_gear_drive_visual.stl" scale="1.0 1.0 1.0"/>
      </geometry>
      <material name="hip_yaw_gear_drive_visual_material"/>
    </visual>
  </link>
  <link name="left_hip_yaw_drive_body">
    <inertial>
      <origin xyz="0.0 0.0 0.0" rpy="0.0 0.0 0.0"/>
      <mass value="0.001"/>
      <inertia ixx="1e-09" iyy="1e-09" izz="1e-09" ixy="0" ixz="0" iyz="0"/>
    </inertial>
  </link>
  <joint type="fixed" name="left_hip_yaw_drive">
    <parent link="left_hip_yaw_link"/>
    <child link="left_hip_yaw_drive_body"/>
    <origin xyz="-0.0192 -0.0002 1.12946e-14" rpy="0.0 0.0 0.0"/>
  </joint>
  <joint type="fixed" name="left_hip_yaw_drive_offset">
    <parent link="left_hip_yaw_drive_body"/>
    <child link="left_hip_yaw_gear_drive"/>
    <origin xyz="0.0 0.0 0.0" rpy="0.0 0.0 0.0"/>
  </joint>
  <link name="left_knee_link">
    <inertial>
      <origin xyz="0.00452332 0.019 -0.0505695" rpy="1.5708 0.0 -0.00161648"/>
      <mass value="0.029"/>
      <inertia ixx="5.213560232621943e-05" iyy="4.2370100000000016e-05" izz="1.2975397673780589e-05" ixy="0" ixz="0" iyz="0"/>
    </inertial>
    <visual name="left_knee_link_visual">
      <origin xyz="0.00452332 0.019 -0.0505695" rpy="-4.44089e-16 1.13243e-14 3.55271e-15"/>
      <geometry>
        <mesh filename="assets/left_knee_link_visual.stl" scale="1.0 1.0 1.0"/>
      </geometry>
      <material name="knee_link_visual_material"/>
    </visual>
    <collision name="left_knee_link_collision">
      <origin xyz="4.99872e-09 0.019 -0.0511526" rpy="-4.44089e-16 1.13243e-14 3.55271e-15"/>
      <geometry>
        <box type="box" size="0.03 0.046 0.132305"/>
      </geometry>
    </collision>
  </link>
  <link name="left_knee_body">
    <inertial>
      <origin xyz="0.0 0.0 0.0" rpy="0.0 0.0 0.0"/>
      <mass value="0.001"/>
      <inertia ixx="1e-09" iyy="1e-09" izz="1e-09" ixy="0" ixz="0" iyz="0"/>
    </inertial>
  </link>
  <joint type="revolute" name="left_knee">
    <parent link="left_hip_yaw_link"/>
    <child link="left_knee_body"/>
    <origin xyz="-4.78197e-16 -0.019 -0.0445" rpy="0.0 0.0 0.0"/>
    <axis xyz="0.0 -1.0 0.0"/>
    <limit lower="-2.0943951023931953" upper="0.0" effort="100" velocity="100"/>
  </joint>
  <joint type="fixed" name="left_knee_offset">
    <parent link="left_knee_body"/>
    <child link="left_knee_link"/>
    <origin xyz="0.0 0.0 0.0" rpy="0.0 0.0 0.0"/>
  </joint>
  <link name="left_ankle_pitch_link">
    <inertial>
      <origin xyz="-0.0179692 0.0188074 0.0120892" rpy="-0.309911 -1.56268 -2.80891"/>
      <mass value="0.172721"/>
      <inertia ixx="0.00012042651182353205" iyy="0.00010548652629092307" izz="4.6354161885544694e-05" ixy="0" ixz="0" iyz="0"/>
    </inertial>
    <visual name="left_ankle_pitch_link_visual">
      <origin xyz="-0.0179692 0.0188074 0.0120892" rpy="-8.88178e-16 1.13243e-14 3.55271e-15"/>
      <geometry>
        <mesh filename="assets/left_ankle_pitch_link_visual.stl" scale="1.0 1.0 1.0"/>
      </geometry>
      <material name="ankle_pitch_link_visual_material"/>
    </visual>
    <collision name="left_ankle_pitch_link_collision">
      <origin xyz="-0.01855 0.0168 0.012" rpy="-8.88178e-16 1.13243e-14 3.55271e-15"/>
      <geometry>
        <box type="box" size="0.0869 0.0424 0.0465"/>
      </geometry>
    </collision>
  </link>
  <link name="left_ankle_pitch_body">
    <inertial>
      <origin xyz="0.0 0.0 0.0" rpy="0.0 0.0 0.0"/>
      <mass value="0.001"/>
      <inertia ixx="1e-09" iyy="1e-09" izz="1e-09" ixy="0" ixz="0" iyz="0"/>
    </inertial>
  </link>
  <joint type="revolute" name="left_ankle_pitch">
    <parent link="left_knee_link"/>
    <child link="left_ankle_pitch_body"/>
    <origin xyz="-7.16755e-18 -4.83405e-17 -0.11" rpy="0.0 0.0 0.0"/>
    <axis xyz="0.0 1.0 0.0"/>
    <limit lower="-1.8325957145940461" upper="0.9599310885968813" effort="100" velocity="100"/>
  </joint>
  <joint type="fixed" name="left_ankle_pitch_offset">
    <parent link="left_ankle_pitch_body"/>
    <child link="left_ankle_pitch_link"/>
    <origin xyz="0.0 0.0 0.0" rpy="0.0 0.0 0.0"/>
  </joint>
  <link name="left_ankle_roll_link">
    <inertial>
      <origin xyz="0.0358432 -6.70173e-08 -0.0267229" rpy="-0.104864 -1.8642e-05 1.57073"/>
      <mass value="0.039"/>
      <inertia ixx="3.0430700009149677e-05" iyy="2.9026636819382057e-05" izz="8.651143171468227e-06" ixy="0" ixz="0" iyz="0"/>
    </inertial>
    <visual name="left_ankle_roll_link_visual">
      <origin xyz="0.0358432 -6.70173e-08 -0.0267229" rpy="-1.08514e-15 4.88054e-13 3.78202e-15"/>
      <geometry>
        <mesh filename="assets/left_ankle_roll_link_visual.stl" scale="1.0 1.0 1.0"/>
      </geometry>
      <material name="ankle_roll_link_visual_material"/>
    </visual>
    <collision name="left_ankle_roll_link_collision">
      <origin xyz="0.0358432 -6.70173e-08 -0.0267229" rpy="-1.08514e-15 4.88054e-13 3.78202e-15"/>
      <geometry>
        <mesh filename="assets/left_ankle_roll_link_collision.stl" scale="1.0 1.0 1.0"/>
      </geometry>
    </collision>
  </link>
  <link name="left_ankle_roll_body">
    <inertial>
      <origin xyz="0.0 0.0 0.0" rpy="0.0 0.0 0.0"/>
      <mass value="0.001"/>
      <inertia ixx="1e-09" iyy="1e-09" izz="1e-09" ixy="0" ixz="0" iyz="0"/>
    </inertial>
  </link>
  <joint type="revolute" name="left_ankle_roll">
    <parent link="left_ankle_pitch_link"/>
    <child link="left_ankle_roll_body"/>
    <origin xyz="-0.023 0.019 1.74256e-14" rpy="0.0 0.0 0.0"/>
    <axis xyz="1.0 0.0 0.0"/>
    <limit lower="-1.221730476395942" upper="1.2217304763961192" effort="100" velocity="100"/>
  </joint>
  <joint type="fixed" name="left_ankle_roll_offset">
    <parent link="left_ankle_roll_body"/>
    <child link="left_ankle_roll_link"/>
    <origin xyz="0.0 0.0 0.0" rpy="0.0 0.0 0.0"/>
  </joint>
  <link name="right_hip_pitch_link">
    <inertial>
      <origin xyz="-0.0202238 -0.0188253 -0.0117862" rpy="1.57611 0.00223173 1.57906"/>
      <mass value="0.188221"/>
      <inertia ixx="0.00013079657189784364" iyy="0.00011376770875309217" izz="5.023341934906427e-05" ixy="0" ixz="0" iyz="0"/>
    </inertial>
    <visual name="right_hip_pitch_link_visual">
      <origin xyz="-0.0202238 -0.0188253 -0.0117862" rpy="-8.88178e-16 -4.44089e-16 -2.87548e-14"/>
      <geometry>
        <mesh filename="assets/right_hip_pitch_link_visual.stl" scale="1.0 1.0 1.0"/>
      </geometry>
      <material name="hip_pitch_link_visual_material"/>
    </visual>
    <collision name="right_hip_pitch_link_collision">
      <origin xyz="-0.0179687 -0.0168 -0.012" rpy="-8.88178e-16 -4.44089e-16 -2.87548e-14"/>
      <geometry>
        <box type="box" size="0.0857376 0.0424 0.0465"/>
      </geometry>
    </collision>
  </link>
  <link name="right_hip_pitch_body">
    <inertial>
      <origin xyz="0.0 0.0 0.0" rpy="0.0 0.0 0.0"/>
      <mass value="0.001"/>
      <inertia ixx="1e-09" iyy="1e-09" izz="1e-09" ixy="0" ixz="0" iyz="0"/>
    </inertial>
  </link>
  <joint type="revolute" name="right_hip_pitch">
    <parent link="pelvis_link"/>
    <child link="right_hip_pitch_body"/>
    <origin xyz="-0.02275 -0.018 -0.0481" rpy="0.0 0.0 0.0"/>
    <axis xyz="0.0 -1.0 0.0"/>
    <limit lower="-0.7853981633974225" upper="2.3561944901923706" effort="100" velocity="100"/>
  </joint>
  <joint type="fixed" name="right_hip_pitch_offset">
    <parent link="right_hip_pitch_body"/>
    <child link="right_hip_pitch_link"/>
    <origin xyz="0.0 0.0 0.0" rpy="0.0 0.0 0.0"/>
  </joint>
  <link name="right_hip_roll_link">
    <inertial>
      <origin xyz="0.0246449 -3.2234e-06 -0.0172318" rpy="0.0190768 -0.000313585 0.000387817"/>
      <mass value="0.022"/>
      <inertia ixx="9.951740710603494e-06" iyy="8.778876227225876e-06" izz="4.309323062170636e-06" ixy="0" ixz="0" iyz="0"/>
    </inertial>
    <visual name="right_hip_roll_link_visual">
      <origin xyz="0.0246449 -3.2234e-06 -0.0172318" rpy="-8.88178e-16 -4.44089e-16 -2.88658e-14"/>
      <geometry>
        <mesh filename="assets/right_hip_roll_link_visual.stl" scale="1.0 1.0 1.0"/>
      </geometry>
      <material name="hip_roll_link_visual_material"/>
    </visual>
  </link>
  <link name="right_hip_roll_body">
    <inertial>
      <origin xyz="0.0 0.0 0.0" rpy="0.0 0.0 0.0"/>
      <mass value="0.001"/>
      <inertia ixx="1e-09" iyy="1e-09" izz="1e-09" ixy="0" ixz="0" iyz="0"/>
    </inertial>
  </link>
  <joint type="revolute" name="right_hip_roll">
    <parent link="right_hip_pitch_link"/>
    <child link="right_hip_roll_body"/>
    <origin xyz="-0.0228375 -0.019 -0.024" rpy="0.0 0.0 0.0"/>
    <axis xyz="1.0 0.0 0.0"/>
    <limit lower="-1.5707963267948664" upper="0.7853981633974785" effort="100" velocity="100"/>
  </joint>
  <joint type="fixed" name="right_hip_roll_offset">
    <parent link="right_hip_roll_body"/>
    <child link="right_hip_roll_link"/>
    <origin xyz="0.0 0.0 0.0" rpy="0.0 0.0 0.0"/>
  </joint>
  <link name="right_hip_yaw_link">
    <inertial>
      <origin xyz="-0.00967257 -0.00117152 -0.0353303" rpy="-0.390028 0.158048 -0.0399683"/>
      <mass value="0.159688"/>
      <inertia ixx="7.952647039873602e-05" iyy="6.276452677935325e-05" izz="5.035170282191073e-05" ixy="0" ixz="0" iyz="0"/>
    </inertial>
    <visual name="right_hip_yaw_link_visual">
      <origin xyz="-0.00967257 -0.00117152 -0.0353303" rpy="2.79776e-14 -9.32587e-15 -3.01981e-14"/>
      <geometry>
        <mesh filename="assets/right_hip_yaw_link_visual.stl" scale="1.0 1.0 1.0"/>
      </geometry>
      <material name="hip_yaw_link_visual_material"/>
    </visual>
    <collision name="right_hip_yaw_link_collision">
      <origin xyz="-0.009525 -0.000574999 -0.031475" rpy="2.79776e-14 -9.32587e-15 -3.01981e-14"/>
      <geometry>
        <box type="box" size="0.05905 0.04795 0.06295"/>
      </geometry>
    </collision>
  </link>
  <link name="right_hip_yaw_driven_body">
    <inertial>
      <origin xyz="0.0 0.0 0.0" rpy="0.0 0.0 0.0"/>
      <mass value="0.001"/>
      <inertia ixx="1e-09" iyy="1e-09" izz="1e-09" ixy="0" ixz="0" iyz="0"/>
    </inertial>
  </link>
  <joint type="revolute" name="right_hip_yaw_driven">
    <parent link="right_hip_roll_link"/>
    <child link="right_hip_yaw_driven_body"/>
    <origin xyz="0.023 -6.96693e-16 -0.033" rpy="0.0 0.0 0.0"/>
    <axis xyz="0.0 0.0 -1.0"/>
    <limit lower="-1.570796326794897" upper="1.5707963267948961" effort="100" velocity="100"/>
  </joint>
  <joint type="fixed" name="right_hip_yaw_driven_offset">
    <parent link="right_hip_yaw_driven_body"/>
    <child link="right_hip_yaw_link"/>
    <origin xyz="0.0 0.0 0.0" rpy="0.0 0.0 0.0"/>
  </joint>
  <link name="right_hip_yaw_gear_drive">
    <inertial>
      <origin xyz="-9.06167e-17 3.37738e-16 0.00175" rpy="1.5708 -1.5708 0.0"/>
      <mass value="0.001"/>
      <inertia ixx="4.7219e-08" iyy="2.46213e-08" izz="2.46213e-08" ixy="0" ixz="0" iyz="0"/>
    </inertial>
    <visual name="right_hip_yaw_gear_drive_visual">
      <origin xyz="-9.16238e-17 3.37849e-16 0.00175" rpy="2.81116e-14 -9.32587e-15 -1.65935e-13"/>
      <geometry>
        <mesh filename="assets/right_hip_yaw_gear_drive_visual.stl" scale="1.0 1.0 1.0"/>
      </geometry>
      <material name="hip_yaw_gear_drive_visual_material"/>
    </visual>
  </link>
  <link name="right_hip_yaw_drive_body">
    <inertial>
      <origin xyz="0.0 0.0 0.0" rpy="0.0 0.0 0.0"/>
      <mass value="0.001"/>
      <inertia ixx="1e-09" iyy="1e-09" izz="1e-09" ixy="0" ixz="0" iyz="0"/>
    </inertial>
  </link>
  <joint type="fixed" name="right_hip_yaw_drive">
    <parent link="right_hip_yaw_link"/>
    <child link="right_hip_yaw_drive_body"/>
    <origin xyz="-0.0192 0.0002 1.12316e-14" rpy="0.0 0.0 0.0"/>
  </joint>
  <joint type="fixed" name="right_hip_yaw_drive_offset">
    <parent link="right_hip_yaw_drive_body"/>
    <child link="right_hip_yaw_gear_drive"/>
    <origin xyz="0.0 0.0 0.0" rpy="0.0 0.0 0.0"/>
  </joint>
  <link name="right_knee_link">
    <inertial>
      <origin xyz="0.00452332 -0.019 -0.0505695" rpy="1.5708 0.0 0.00161648"/>
      <mass value="0.029"/>
      <inertia ixx="5.213560232621943e-05" iyy="4.2370100000000016e-05" izz="1.2975397673780589e-05" ixy="0" ixz="0" iyz="0"/>
    </inertial>
    <visual name="right_knee_link_visual">
      <origin xyz="0.00452332 -0.019 -0.0505695" rpy="-1.9984e-15 0.0 -3.20688e-14"/>
      <geometry>
        <mesh filename="assets/right_knee_link_visual.stl" scale="1.0 1.0 1.0"/>
      </geometry>
      <material name="knee_link_visual_material"/>
    </visual>
    <collision name="right_knee_link_collision">
      <origin xyz="4.99872e-09 -0.019 -0.0511526" rpy="-1.9984e-15 0.0 -3.20688e-14"/>
      <geometry>
        <box type="box" size="0.03 0.046 0.132305"/>
      </geometry>
    </collision>
  </link>
  <link name="right_knee_body">
    <inertial>
      <origin xyz="0.0 0.0 0.0" rpy="0.0 0.0 0.0"/>
      <mass value="0.001"/>
      <inertia ixx="1e-09" iyy="1e-09" izz="1e-09" ixy="0" ixz="0" iyz="0"/>
    </inertial>
  </link>
  <joint type="revolute" name="right_knee">
    <parent link="right_hip_yaw_link"/>
    <child link="right_knee_body"/>
    <origin xyz="5.00205e-16 0.019 -0.0445" rpy="0.0 0.0 0.0"/>
    <axis xyz="0.0 1.0 0.0"/>
    <limit lower="0.0" upper="2.0943951023931953" effort="100" velocity="100"/>
  </joint>
  <joint type="fixed" name="right_knee_offset">
    <parent link="right_knee_body"/>
    <child link="right_knee_link"/>
    <origin xyz="0.0 0.0 0.0" rpy="0.0 0.0 0.0"/>
  </joint>
  <link name="right_ankle_pitch_link">
    <inertial>
      <origin xyz="-0.0179692 -0.018812 0.0120892" rpy="-2.92992 -1.56236 -0.234444"/>
      <mass value="0.172721"/>
      <inertia ixx="0.00012042708718664342" iyy="0.00010548657093012269" izz="4.635384188323381e-05" ixy="0" ixz="0" iyz="0"/>
    </inertial>
    <visual name="right_ankle_pitch_link_visual">
      <origin xyz="-0.0179692 -0.018812 0.0120892" rpy="-5.55112e-16 -4.44089e-16 -3.23742e-14"/>
      <geometry>
        <mesh filename="assets/right_ankle_pitch_link_visual.stl" scale="1.0 1.0 1.0"/>
      </geometry>
      <material name="ankle_pitch_link_visual_material"/>
    </visual>
    <collision name="right_ankle_pitch_link_collision">
      <origin xyz="-0.01855 -0.0168 0.012" rpy="-5.55112e-16 -4.44089e-16 -3.23742e-14"/>
      <geometry>
        <box type="box" size="0.0869 0.0424 0.0465"/>
      </geometry>
    </collision>
  </link>
  <link name="right_ankle_pitch_body">
    <inertial>
      <origin xyz="0.0 0.0 0.0" rpy="0.0 0.0 0.0"/>
      <mass value="0.001"/>
      <inertia ixx="1e-09" iyy="1e-09" izz="1e-09" ixy="0" ixz="0" iyz="0"/>
    </inertial>
  </link>
  <joint type="revolute" name="right_ankle_pitch">
    <parent link="right_knee_link"/>
    <child link="right_ankle_pitch_body"/>
    <origin xyz="-1.14853e-17 -2.25611e-16 -0.11" rpy="0.0 0.0 0.0"/>
    <axis xyz="0.0 -1.0 0.0"/>
    <limit lower="-0.9599310885968813" upper="1.8325957145940461" effort="100" velocity="100"/>
  </joint>
  <joint type="fixed" name="right_ankle_pitch_offset">
    <parent link="right_ankle_pitch_body"/>
    <child link="right_ankle_pitch_link"/>
    <origin xyz="0.0 0.0 0.0" rpy="0.0 0.0 0.0"/>
  </joint>
  <link name="right_ankle_roll_link">
    <inertial>
      <origin xyz="0.0358432 -6.70173e-08 -0.0267229" rpy="-0.104864 -1.8642e-05 1.57073"/>
      <mass value="0.039"/>
      <inertia ixx="3.0430700009149677e-05" iyy="2.9026636819382057e-05" izz="8.651143171468227e-06" ixy="0" ixz="0" iyz="0"/>
    </inertial>
    <visual name="right_ankle_roll_link_visual">
      <origin xyz="0.0358432 -6.70173e-08 -0.0267229" rpy="-8.88178e-16 5.12257e-13 -3.19744e-14"/>
      <geometry>
        <mesh filename="assets/right_ankle_roll_link_visual.stl" scale="1.0 1.0 1.0"/>
      </geometry>
      <material name="ankle_roll_link_visual_material"/>
    </visual>
    <collision name="right_ankle_roll_link_collision">
      <origin xyz="0.0358432 -6.70173e-08 -0.0267229" rpy="-8.88178e-16 5.12257e-13 -3.19744e-14"/>
      <geometry>
        <mesh filename="assets/right_ankle_roll_link_collision.stl" scale="1.0 1.0 1.0"/>
      </geometry>
    </collision>
  </link>
  <link name="right_ankle_roll_body">
    <inertial>
      <origin xyz="0.0 0.0 0.0" rpy="0.0 0.0 0.0"/>
      <mass value="0.001"/>
      <inertia ixx="1e-09" iyy="1e-09" izz="1e-09" ixy="0" ixz="0" iyz="0"/>
    </inertial>
  </link>
  <joint type="revolute" name="right_ankle_roll">
    <parent link="right_ankle_pitch_link"/>
    <child link="right_ankle_roll_body"/>
    <origin xyz="-0.023 -0.019 1.78974e-14" rpy="0.0 0.0 0.0"/>
    <axis xyz="1.0 0.0 0.0"/>
    <limit lower="-1.221730476396059" upper="1.2217304763960022" effort="100" velocity="100"/>
  </joint>
  <joint type="fixed" name="right_ankle_roll_offset">
    <parent link="right_ankle_roll_body"/>
    <child link="right_ankle_roll_link"/>
    <origin xyz="0.0 0.0 0.0" rpy="0.0 0.0 0.0"/>
  </joint>
  <link name="left_shoulder_pitch_link">
    <inertial>
      <origin xyz="1.99287e-19 0.0129132 6.38666e-18" rpy="3.14159 -1.5708 0.0"/>
      <mass value="0.015"/>
      <inertia ixx="6.99606e-06" iyy="6.13264e-06" izz="3.20331e-06" ixy="0" ixz="0" iyz="0"/>
    </inertial>
    <visual name="left_shoulder_pitch_link_visual">
      <origin xyz="1.99287e-19 0.0129132 6.38666e-18" rpy="2.12006e-30 4.44089e-16 -3.13956e-16"/>
      <geometry>
        <mesh filename="assets/left_shoulder_pitch_link_visual.stl" scale="1.0 1.0 1.0"/>
      </geometry>
      <material name="shoulder_pitch_link_visual_material"/>
    </visual>
  </link>
  <link name="left_shoulder_pitch_body">
    <inertial>
      <origin xyz="0.0 0.0 0.0" rpy="0.0 0.0 0.0"/>
      <mass value="0.001"/>
      <inertia ixx="1e-09" iyy="1e-09" izz="1e-09" ixy="0" ixz="0" iyz="0"/>
    </inertial>
  </link>
  <joint type="revolute" name="left_shoulder_pitch">
    <parent link="torso"/>
    <child link="left_shoulder_pitch_body"/>
    <origin xyz="-0.0200079 0.067 0.10175" rpy="0.0 0.0 0.0"/>
    <axis xyz="0.0 1.0 0.0"/>
    <limit lower="-3.1415926535897913" upper="3.141592653589795" effort="100" velocity="100"/>
  </joint>
  <joint type="fixed" name="left_shoulder_pitch_offset">
    <parent link="left_shoulder_pitch_body"/>
    <child link="left_shoulder_pitch_link"/>
    <origin xyz="0.0 0.0 0.0" rpy="0.0 0.0 0.0"/>
  </joint>
  <link name="left_shoulder_roll_link">
    <inertial>
      <origin xyz="0.0185402 0.0117736 -0.00203648" rpy="-1.55721 -1.33056 -1.491"/>
      <mass value="0.1152"/>
      <inertia ixx="3.485900290216656e-05" iyy="3.210267524717292e-05" izz="2.6556321850660507e-05" ixy="0" ixz="0" iyz="0"/>
    </inertial>
    <visual name="left_shoulder_roll_link_visual">
      <origin xyz="0.0185402 0.0117736 -0.00203648" rpy="1.11022e-16 4.44089e-16 -3.33066e-16"/>
      <geometry>
        <mesh filename="assets/left_shoulder_roll_link_visual.stl" scale="1.0 1.0 1.0"/>
      </geometry>
      <material name="shoulder_roll_link_visual_material"/>
    </visual>
    <collision name="left_shoulder_roll_link_collision">
      <origin xyz="0.01855 0.012 -0.003" rpy="1.11022e-16 4.44089e-16 -3.33066e-16"/>
      <geometry>
        <box type="box" size="0.0409 0.0465 0.046"/>
      </geometry>
    </collision>
  </link>
  <link name="left_shoulder_roll_body">
    <inertial>
      <origin xyz="0.0 0.0 0.0" rpy="0.0 0.0 0.0"/>
      <mass value="0.001"/>
      <inertia ixx="1e-09" iyy="1e-09" izz="1e-09" ixy="0" ixz="0" iyz="0"/>
    </inertial>
  </link>
  <joint type="revolute" name="left_shoulder_roll">
    <parent link="left_shoulder_pitch_link"/>
    <child link="left_shoulder_roll_body"/>
    <origin xyz="-0.019 0.027 -1.67365e-15" rpy="0.0 0.0 0.0"/>
    <axis xyz="1.0 0.0 0.0"/>
    <limit lower="-0.43633231299806097" upper="1.570796326795418" effort="100" velocity="100"/>
  </joint>
  <joint type="fixed" name="left_shoulder_roll_offset">
    <parent link="left_shoulder_roll_body"/>
    <child link="left_shoulder_roll_link"/>
    <origin xyz="0.0 0.0 0.0" rpy="0.0 0.0 0.0"/>
  </joint>
  <link name="left_shoulder_gear_drive">
    <inertial>
      <origin xyz="2.34689e-15 1.16905e-15 -0.00662386" rpy="1.5708 -1.5708 0.0"/>
      <mass value="0.004"/>
      <inertia ixx="2.87762e-07" iyy="1.9527e-07" izz="1.9527e-07" ixy="0" ixz="0" iyz="0"/>
    </inertial>
    <visual name="left_shoulder_gear_drive_visual">
      <origin xyz="2.34689e-15 1.17341e-15 -0.00662386" rpy="3.41744e-13 6.52811e-13 8.57596e-14"/>
      <geometry>
        <mesh filename="assets/left_shoulder_gear_drive_visual.stl" scale="1.0 1.0 1.0"/>
      </geometry>
      <material name="shoulder_gear_drive_visual_material"/>
    </visual>
  </link>
  <link name="left_shoulder_yaw_drive_body">
    <inertial>
      <origin xyz="0.0 0.0 0.0" rpy="0.0 0.0 0.0"/>
      <mass value="0.001"/>
      <inertia ixx="1e-09" iyy="1e-09" izz="1e-09" ixy="0" ixz="0" iyz="0"/>
    </inertial>
  </link>
  <joint type="fixed" name="left_shoulder_yaw_drive">
    <parent link="left_shoulder_roll_link"/>
    <child link="left_shoulder_yaw_drive_body"/>
    <origin xyz="0.019 0.024 -0.019" rpy="0.0 0.0 0.0"/>
  </joint>
  <joint type="fixed" name="left_shoulder_yaw_drive_offset">
    <parent link="left_shoulder_yaw_drive_body"/>
    <child link="left_shoulder_gear_drive"/>
    <origin xyz="0.0 0.0 0.0" rpy="0.0 0.0 0.0"/>
  </joint>
  <link name="left_shoulder_yaw_link">
    <inertial>
      <origin xyz="-5.55746e-18 1.46642e-16 -0.0257843" rpy="0.0 0.0 1.5708"/>
      <mass value="0.0247439"/>
      <inertia ixx="1.54061e-05" iyy="1.01507e-05" izz="6.98599e-06" ixy="0" ixz="0" iyz="0"/>
    </inertial>
    <visual name="left_shoulder_yaw_link_visual">
      <origin xyz="-5.41211e-18 1.4858e-16 -0.0257843" rpy="-1.89904e-13 4.6696e-13 1.78375e-14"/>
      <geometry>
        <mesh filename="assets/left_shoulder_yaw_link_visual.stl" scale="1.0 1.0 1.0"/>
      </geometry>
      <material name="shoulder_yaw_link_visual_material"/>
    </visual>
    <collision name="left_shoulder_yaw_link_collision">
      <origin xyz="-1.47382e-17 4.9127400000000006e-18 -0.04425" rpy="-1.89904e-13 4.6696e-13 1.78375e-14"/>
      <geometry>
        <box type="box" size="0.046 0.025985 0.054214"/>
      </geometry>
    </collision>
  </link>
  <link name="left_shoulder_yaw_driven_body">
    <inertial>
      <origin xyz="0.0 0.0 0.0" rpy="0.0 0.0 0.0"/>
      <mass value="0.001"/>
      <inertia ixx="1e-09" iyy="1e-09" izz="1e-09" ixy="0" ixz="0" iyz="0"/>
    </inertial>
  </link>
  <joint type="revolute" name="left_shoulder_yaw_driven">
    <parent link="left_shoulder_roll_link"/>
    <child link="left_shoulder_yaw_driven_body"/>
    <origin xyz="0.019 3.58104e-10 -0.025" rpy="0.0 0.0 0.0"/>
    <axis xyz="0.0 0.0 -1.0"/>
    <limit lower="-3.1415926535898104" upper="3.141592653589776" effort="100" velocity="100"/>
  </joint>
  <joint type="fixed" name="left_shoulder_yaw_driven_offset">
    <parent link="left_shoulder_yaw_driven_body"/>
    <child link="left_shoulder_yaw_link"/>
    <origin xyz="0.0 0.0 0.0" rpy="0.0 0.0 0.0"/>
  </joint>
  <link name="left_elbow_roll_link">
    <inertial>
      <origin xyz="0.0185402 0.0117736 -0.00203648" rpy="1.58439 -1.33056 1.65059"/>
      <mass value="0.1152"/>
      <inertia ixx="3.485900290216656e-05" iyy="3.210267524717292e-05" izz="2.6556321850660507e-05" ixy="0" ixz="0" iyz="0"/>
    </inertial>
    <visual name="left_elbow_roll_link_visual">
      <origin xyz="0.0185402 0.0117736 -0.00203648" rpy="0.0 4.44089e-16 0.0"/>
      <geometry>
        <mesh filename="assets/left_elbow_roll_link_visual.stl" scale="1.0 1.0 1.0"/>
      </geometry>
      <material name="elbow_roll_link_visual_material"/>
    </visual>
    <collision name="left_elbow_roll_link_collision">
      <origin xyz="0.01855 0.012 -0.003" rpy="0.0 4.44089e-16 0.0"/>
      <geometry>
        <box type="box" size="0.0409 0.0465 0.046"/>
      </geometry>
    </collision>
  </link>
  <link name="left_elbow_roll_body">
    <inertial>
      <origin xyz="0.0 0.0 0.0" rpy="0.0 0.0 0.0"/>
      <mass value="0.001"/>
      <inertia ixx="1e-09" iyy="1e-09" izz="1e-09" ixy="0" ixz="0" iyz="0"/>
    </inertial>
  </link>
  <joint type="revolute" name="left_elbow_roll">
    <parent link="left_shoulder_yaw_link"/>
    <child link="left_elbow_roll_body"/>
    <origin xyz="-0.019 -6.66967e-17 -0.061" rpy="0.0 0.0 0.0"/>
    <axis xyz="1.0 0.0 0.0"/>
    <limit lower="-2.268928027592625" upper="1.9198621771937663" effort="100" velocity="100"/>
  </joint>
  <joint type="fixed" name="left_elbow_roll_offset">
    <parent link="left_elbow_roll_body"/>
    <child link="left_elbow_roll_link"/>
    <origin xyz="0.0 0.0 0.0" rpy="0.0 0.0 0.0"/>
  </joint>
  <link name="left_elbow_gear_drive">
    <inertial>
      <origin xyz="-2.35162e-15 -1.16306e-15 -0.00662386" rpy="1.5708 -1.5708 0.0"/>
      <mass value="0.004"/>
      <inertia ixx="2.87762e-07" iyy="1.9527e-07" izz="1.9527e-07" ixy="0" ixz="0" iyz="0"/>
    </inertial>
    <visual name="left_elbow_gear_drive_visual">
      <origin xyz="-2.35162e-15 -1.16573e-15 -0.00662386" rpy="-1.56319e-13 5.04041e-13 8.34888e-14"/>
      <geometry>
        <mesh filename="assets/left_elbow_gear_drive_visual.stl" scale="1.0 1.0 1.0"/>
      </geometry>
      <material name="elbow_gear_drive_visual_material"/>
    </visual>
  </link>
  <link name="left_elbow_yaw_drive_body">
    <inertial>
      <origin xyz="0.0 0.0 0.0" rpy="0.0 0.0 0.0"/>
      <mass value="0.001"/>
      <inertia ixx="1e-09" iyy="1e-09" izz="1e-09" ixy="0" ixz="0" iyz="0"/>
    </inertial>
  </link>
  <joint type="fixed" name="left_elbow_yaw_drive">
    <parent link="left_elbow_roll_link"/>
    <child link="left_elbow_yaw_drive_body"/>
    <origin xyz="0.019 0.024 -0.019" rpy="0.0 0.0 0.0"/>
  </joint>
  <joint type="fixed" name="left_elbow_yaw_drive_offset">
    <parent link="left_elbow_yaw_drive_body"/>
    <child link="left_elbow_gear_drive"/>
    <origin xyz="0.0 0.0 0.0" rpy="0.0 0.0 0.0"/>
  </joint>
  <link name="left_elbow_yaw_link">
    <inertial>
      <origin xyz="2.3429e-12 0.00604452 -0.0333598" rpy="0.600986 0.0 0.0"/>
      <mass value="0.0295299"/>
      <inertia ixx="2.81941e-05" iyy="1.8819699946116415e-05" izz="1.146310005388359e-05" ixy="0" ixz="0" iyz="0"/>
    </inertial>
    <visual name="left_elbow_yaw_link_visual">
      <origin xyz="2.3429e-12 0.00604452 -0.0333598" rpy="-4.80822e-13 1.51879e-13 -1.83062e-13"/>
      <geometry>
        <mesh filename="assets/left_elbow_yaw_link_visual.stl" scale="1.0 1.0 1.0"/>
      </geometry>
      <material name="elbow_yaw_link_visual_material"/>
    </visual>
    <collision name="left_elbow_yaw_link_collision">
      <origin xyz="-1.85713e-17 0.00335 -0.04475" rpy="-4.80822e-13 1.51879e-13 -1.83062e-13"/>
      <geometry>
        <box type="box" size="0.025985 0.0593 0.055126"/>
      </geometry>
    </collision>
  </link>
  <link name="left_elbow_yaw_driven_body">
    <inertial>
      <origin xyz="0.0 0.0 0.0" rpy="0.0 0.0 0.0"/>
      <mass value="0.001"/>
      <inertia ixx="1e-09" iyy="1e-09" izz="1e-09" ixy="0" ixz="0" iyz="0"/>
    </inertial>
  </link>
  <joint type="revolute" name="left_elbow_yaw_driven">
    <parent link="left_elbow_roll_link"/>
    <child link="left_elbow_yaw_driven_body"/>
    <origin xyz="0.019 3.58086e-10 -0.025" rpy="0.0 0.0 0.0"/>
    <axis xyz="0.0 0.0 -1.0"/>
    <limit lower="-3.1415926535895933" upper="3.141592653589993" effort="100" velocity="100"/>
  </joint>
  <joint type="fixed" name="left_elbow_yaw_driven_offset">
    <parent link="left_elbow_yaw_driven_body"/>
    <child link="left_elbow_yaw_link"/>
    <origin xyz="0.0 0.0 0.0" rpy="0.0 0.0 0.0"/>
  </joint>
  <link name="left_wrist_pitch_link">
    <inertial>
      <origin xyz="-0.000415054 -0.021867 0.0114965" rpy="1.49727 -0.0905553 1.57074"/>
      <mass value="0.1276"/>
      <inertia ixx="4.163705409382504e-05" iyy="3.5702593704251416e-05" izz="3.2970352201923534e-05" ixy="0" ixz="0" iyz="0"/>
    </inertial>
    <visual name="left_wrist_pitch_link_visual">
      <origin xyz="-0.000415054 -0.021867 0.0114965" rpy="0.0 4.44089e-16 0.0"/>
      <geometry>
        <mesh filename="assets/left_wrist_pitch_link_visual.stl" scale="1.0 1.0 1.0"/>
      </geometry>
      <material name="wrist_pitch_link_visual_material"/>
    </visual>
    <collision name="left_wrist_pitch_link_collision">
      <origin xyz="-0.00045 -0.0215 0.012" rpy="0.0 4.44089e-16 0.0"/>
      <geometry>
        <box type="box" size="0.0409 0.045 0.0465"/>
      </geometry>
    </collision>
  </link>
  <link name="left_wrist_pitch_driven_body">
    <inertial>
      <origin xyz="0.0 0.0 0.0" rpy="0.0 0.0 0.0"/>
      <mass value="0.001"/>
      <inertia ixx="1e-09" iyy="1e-09" izz="1e-09" ixy="0" ixz="0" iyz="0"/>
    </inertial>
  </link>
  <joint type="revolute" name="left_wrist_pitch_driven">
    <parent link="left_elbow_yaw_link"/>
    <child link="left_wrist_pitch_driven_body"/>
    <origin xyz="2.52308e-17 0.022 -0.061" rpy="0.0 0.0 0.0"/>
    <axis xyz="0.0 -1.0 0.0"/>
    <limit lower="-2.0943951023930456" upper="2.094395102393345" effort="100" velocity="100"/>
  </joint>
  <joint type="fixed" name="left_wrist_pitch_driven_offset">
    <parent link="left_wrist_pitch_driven_body"/>
    <child link="left_wrist_pitch_link"/>
    <origin xyz="0.0 0.0 0.0" rpy="0.0 0.0 0.0"/>
  </joint>
  <link name="left_wrist_gear_drive">
    <inertial>
      <origin xyz="-2.9081e-16 0.00503438 -4.09694e-15" rpy="1.5708 -1.5708 0.0"/>
      <mass value="0.003"/>
      <inertia ixx="2.24433e-07" iyy="1.33264e-07" izz="1.33264e-07" ixy="0" ixz="0" iyz="0"/>
    </inertial>
    <visual name="left_wrist_gear_drive_visual">
      <origin xyz="-2.9081e-16 0.00503438 -4.09451e-15" rpy="-7.90479e-13 5.77094e-13 -1.84297e-13"/>
      <geometry>
        <mesh filename="assets/left_wrist_gear_drive_visual.stl" scale="1.0 1.0 1.0"/>
      </geometry>
      <material name="wrist_gear_drive_visual_material"/>
    </visual>
  </link>
  <link name="left_wrist_pitch_drive_body">
    <inertial>
      <origin xyz="0.0 0.0 0.0" rpy="0.0 0.0 0.0"/>
      <mass value="0.001"/>
      <inertia ixx="1e-09" iyy="1e-09" izz="1e-09" ixy="0" ixz="0" iyz="0"/>
    </inertial>
  </link>
  <joint type="fixed" name="left_wrist_pitch_drive">
    <parent link="left_wrist_pitch_link"/>
    <child link="left_wrist_pitch_drive_body"/>
    <origin xyz="1.52465e-10 -0.003 0.024" rpy="0.0 0.0 0.0"/>
  </joint>
  <joint type="fixed" name="left_wrist_pitch_drive_offset">
    <parent link="left_wrist_pitch_drive_body"/>
    <child link="left_wrist_gear_drive"/>
    <origin xyz="0.0 0.0 0.0" rpy="0.0 0.0 0.0"/>
  </joint>
  <link name="left_gripper_link">
    <inertial>
      <origin xyz="0.00528675 0.00369019 -0.0303168" rpy="-0.188429 0.12716 1.21855"/>
      <mass value="0.0687174"/>
      <inertia ixx="5.5200807722016286e-05" iyy="5.381204938633472e-05" izz="1.56380428916489e-05" ixy="0" ixz="0" iyz="0"/>
    </inertial>
    <visual name="left_gripper_link_visual">
      <origin xyz="0.00528675 0.00369019 -0.0303168" rpy="0.0 4.44089e-16 0.0"/>
      <geometry>
        <mesh filename="assets/left_gripper_link_visual.stl" scale="1.0 1.0 1.0"/>
      </geometry>
      <material name="gripper_link_visual_material"/>
    </visual>
    <collision name="left_gripper_link_collision">
      <origin xyz="0.019 0.002925 -0.02885" rpy="0.0 4.44089e-16 0.0"/>
      <geometry>
        <box type="box" size="0.09 0.04935 0.0363"/>
      </geometry>
    </collision>
  </link>
  <link name="left_wrist_roll_body">
    <inertial>
      <origin xyz="0.0 0.0 0.0" rpy="0.0 0.0 0.0"/>
      <mass value="0.001"/>
      <inertia ixx="1e-09" iyy="1e-09" izz="1e-09" ixy="0" ixz="0" iyz="0"/>
    </inertial>
  </link>
  <joint type="revolute" name="left_wrist_roll">
    <parent link="left_wrist_pitch_link"/>
    <child link="left_wrist_roll_body"/>
    <origin xyz="-0.019 -0.022 -3.58073e-10" rpy="0.0 0.0 0.0"/>
    <axis xyz="-1.0 0.0 0.0"/>
    <limit lower="-1.5707963267948966" upper="1.5707963267948966" effort="100" velocity="100"/>
  </joint>
  <joint type="fixed" name="left_wrist_roll_offset">
    <parent link="left_wrist_roll_body"/>
    <child link="left_gripper_link"/>
    <origin xyz="0.0 0.0 0.0" rpy="0.0 0.0 0.0"/>
  </joint>
  <link name="left_gripper_gear_drive">
    <inertial>
      <origin xyz="3.35843e-17 -2.99512e-17 -0.0025" rpy="1.5708 -1.5708 0.0"/>
      <mass value="0.00107037"/>
      <inertia ixx="5.01899e-08" iyy="2.73249e-08" izz="2.73249e-08" ixy="0" ixz="0" iyz="0"/>
    </inertial>
    <visual name="left_gripper_gear_drive_visual">
      <origin xyz="3.35843e-17 -2.77556e-17 -0.0025" rpy="-8.88178e-16 -4.44089e-16 -6.21725e-14"/>
      <geometry>
        <mesh filename="assets/left_gripper_gear_drive_visual.stl" scale="1.0 1.0 1.0"/>
      </geometry>
      <material name="gripper_gear_drive_visual_material"/>
    </visual>
  </link>
  <link name="left_gripper_rack_body">
    <inertial>
      <origin xyz="0.0 0.0 0.0" rpy="0.0 0.0 0.0"/>
      <mass value="0.001"/>
      <inertia ixx="1e-09" iyy="1e-09" izz="1e-09" ixy="0" ixz="0" iyz="0"/>
    </inertial>
  </link>
  <joint type="fixed" name="left_gripper_rack">
    <parent link="left_gripper_link"/>
    <child link="left_gripper_rack_body"/>
    <origin xyz="-0.01195 0.0001 -0.0397" rpy="0.0 0.0 0.0"/>
  </joint>
  <joint type="fixed" name="left_gripper_rack_offset">
    <parent link="left_gripper_rack_body"/>
    <child link="left_gripper_gear_drive"/>
    <origin xyz="0.0 0.0 0.0" rpy="0.0 0.0 0.0"/>
  </joint>
  <link name="left_gripper_finger">
    <inertial>
      <origin xyz="0.00981816 0.0160522 -0.0386855" rpy="1.47162 -1.54237 0.116783"/>
      <mass value="0.0265733"/>
      <inertia ixx="1.2681950190120397e-05" iyy="1.0313366970303894e-05" izz="5.642052839575708e-06" ixy="0" ixz="0" iyz="0"/>
    </inertial>
    <visual name="left_gripper_finger_visual">
      <origin xyz="0.00981816 0.0160522 -0.0386855" rpy="4.44089e-16 1.11022e-15 0.0"/>
      <geometry>
        <mesh filename="assets/left_gripper_finger_visual.stl" scale="1.0 1.0 1.0"/>
      </geometry>
      <material name="gripper_finger_visual_material"/>
    </visual>
    <collision name="left_gripper_finger_collision_0">
      <origin xyz="0.0045 0.016125 -0.027" rpy="4.44089e-16 1.11022e-15 0.0"/>
      <geometry>
        <box type="box" size="0.009 0.0407 0.038"/>
      </geometry>
    </collision>
    <collision name="left_gripper_finger_collision_1">
      <origin xyz="0.01075 0.016125 -0.055" rpy="4.44089e-16 1.11022e-15 0.0"/>
      <geometry>
        <box type="box" size="0.0215 0.0407 0.018"/>
      </geometry>
    </collision>
  </link>
  <link name="left_gripper_pinion_body">
    <inertial>
      <origin xyz="0.0 0.0 0.0" rpy="0.0 0.0 0.0"/>
      <mass value="0.001"/>
      <inertia ixx="1e-09" iyy="1e-09" izz="1e-09" ixy="0" ixz="0" iyz="0"/>
    </inertial>
  </link>
  <joint type="prismatic" name="left_gripper_pinion">
    <parent link="left_gripper_link"/>
    <child link="left_gripper_pinion_body"/>
    <origin xyz="-0.026 -0.015975 -0.03985" rpy="0.0 0.0 0.0"/>
    <axis xyz="1.0 0.0 0.0"/>
    <limit lower="-0.0008730000000025674" upper="0.023499999999997433" effort="100" velocity="100"/>
  </joint>
  <joint type="fixed" name="left_gripper_pinion_offset">
    <parent link="left_gripper_pinion_body"/>
    <child link="left_gripper_finger"/>
    <origin xyz="0.0 0.0 0.0" rpy="0.0 0.0 0.0"/>
  </joint>
  <link name="left_gripper_finger_2">
    <inertial>
      <origin xyz="-0.00981816 -0.0160522 -0.0386855" rpy="1.47162 -1.54237 0.116783"/>
      <mass value="0.0265733"/>
      <inertia ixx="1.2681950190120397e-05" iyy="1.0313366970303894e-05" izz="5.642052839575708e-06" ixy="0" ixz="0" iyz="0"/>
    </inertial>
    <visual name="left_gripper_finger_2_visual">
      <origin xyz="-0.00981816 -0.0160522 -0.0386855" rpy="0.0 8.88178e-16 0.0"/>
      <geometry>
        <mesh filename="assets/left_gripper_finger_2_visual.stl" scale="1.0 1.0 1.0"/>
      </geometry>
      <material name="gripper_finger_2_visual_material"/>
    </visual>
    <collision name="left_gripper_finger_2_collision_0">
      <origin xyz="-0.0045 -0.016125 -0.027" rpy="0.0 8.88178e-16 0.0"/>
      <geometry>
        <box type="box" size="0.009 0.0407 0.038"/>
      </geometry>
    </collision>
    <collision name="left_gripper_finger_2_collision_1">
      <origin xyz="-0.01075 -0.016125 -0.055" rpy="0.0 8.88178e-16 0.0"/>
      <geometry>
        <box type="box" size="0.0215 0.0407 0.018"/>
      </geometry>
    </collision>
  </link>
  <link name="left_gripper_pinion_mirror_body">
    <inertial>
      <origin xyz="0.0 0.0 0.0" rpy="0.0 0.0 0.0"/>
      <mass value="0.001"/>
      <inertia ixx="1e-09" iyy="1e-09" izz="1e-09" ixy="0" ixz="0" iyz="0"/>
    </inertial>
  </link>
  <joint type="prismatic" name="left_gripper_pinion_mirror">
    <parent link="left_gripper_link"/>
    <child link="left_gripper_pinion_mirror_body"/>
    <origin xyz="0.064 0.015975 -0.03985" rpy="0.0 0.0 0.0"/>
    <axis xyz="-1.0 0.0 0.0"/>
    <limit lower="-0.0008729999999974465" upper="0.023500000000002554" effort="100" velocity="100"/>
    <mimic joint="left_gripper_pinion" multiplier="1" offset="0"/>
  </joint>
  <joint type="fixed" name="left_gripper_pinion_mirror_offset">
    <parent link="left_gripper_pinion_mirror_body"/>
    <child link="left_gripper_finger_2"/>
    <origin xyz="0.0 0.0 0.0" rpy="0.0 0.0 0.0"/>
  </joint>
  <link name="right_shoulder_pitch_link">
    <inertial>
      <origin xyz="3.0674600000000003e-18 -0.0129132 1.4033500000000001e-18" rpy="3.14159 -1.5708 0.0"/>
      <mass value="0.015"/>
      <inertia ixx="6.99606e-06" iyy="6.13264e-06" izz="3.20331e-06" ixy="0" ixz="0" iyz="0"/>
    </inertial>
    <visual name="right_shoulder_pitch_link_visual">
      <origin xyz="3.06746e-18 -0.0129132 1.40335e-18" rpy="3.3126000000000004e-32 0.0 2.5455800000000003e-18"/>
      <geometry>
        <mesh filename="assets/right_shoulder_pitch_link_visual.stl" scale="1.0 1.0 1.0"/>
      </geometry>
      <material name="shoulder_pitch_link_visual_material"/>
    </visual>
  </link>
  <link name="right_shoulder_pitch_body">
    <inertial>
      <origin xyz="0.0 0.0 0.0" rpy="0.0 0.0 0.0"/>
      <mass value="0.001"/>
      <inertia ixx="1e-09" iyy="1e-09" izz="1e-09" ixy="0" ixz="0" iyz="0"/>
    </inertial>
  </link>
  <joint type="revolute" name="right_shoulder_pitch">
    <parent link="torso"/>
    <child link="right_shoulder_pitch_body"/>
    <origin xyz="-0.0200079 -0.067 0.10175" rpy="0.0 0.0 0.0"/>
    <axis xyz="0.0 -1.0 0.0"/>
    <limit lower="-3.14159265358977" upper="3.141592653589816" effort="100" velocity="100"/>
  </joint>
  <joint type="fixed" name="right_shoulder_pitch_offset">
    <parent link="right_shoulder_pitch_body"/>
    <child link="right_shoulder_pitch_link"/>
    <origin xyz="0.0 0.0 0.0" rpy="0.0 0.0 0.0"/>
  </joint>
  <link name="right_shoulder_roll_link">
    <inertial>
      <origin xyz="-0.0185402 -0.0117736 -0.00203648" rpy="-1.55721 -1.33056 -1.491"/>
      <mass value="0.1152"/>
      <inertia ixx="3.485900290216656e-05" iyy="3.210267524717292e-05" izz="2.6556321850660507e-05" ixy="0" ixz="0" iyz="0"/>
    </inertial>
    <visual name="right_shoulder_roll_link_visual">
      <origin xyz="-0.0185402 -0.0117736 -0.00203648" rpy="0.0 0.0 0.0"/>
      <geometry>
        <mesh filename="assets/right_shoulder_roll_link_visual.stl" scale="1.0 1.0 1.0"/>
      </geometry>
      <material name="shoulder_roll_link_visual_material"/>
    </visual>
    <collision name="right_shoulder_roll_link_collision">
      <origin xyz="-0.01855 -0.012 -0.003" rpy="0.0 0.0 0.0"/>
      <geometry>
        <box type="box" size="0.0409 0.0465 0.046"/>
      </geometry>
    </collision>
  </link>
  <link name="right_shoulder_roll_body">
    <inertial>
      <origin xyz="0.0 0.0 0.0" rpy="0.0 0.0 0.0"/>
      <mass value="0.001"/>
      <inertia ixx="1e-09" iyy="1e-09" izz="1e-09" ixy="0" ixz="0" iyz="0"/>
    </inertial>
  </link>
  <joint type="revolute" name="right_shoulder_roll">
    <parent link="right_shoulder_pitch_link"/>
    <child link="right_shoulder_roll_body"/>
    <origin xyz="0.019 -0.027 -1.42914e-16" rpy="0.0 0.0 0.0"/>
    <axis xyz="-1.0 0.0 0.0"/>
    <limit lower="-0.4363323129980788" upper="1.5707963267954002" effort="100" velocity="100"/>
  </joint>
  <joint type="fixed" name="right_shoulder_roll_offset">
    <parent link="right_shoulder_roll_body"/>
    <child link="right_shoulder_roll_link"/>
    <origin xyz="0.0 0.0 0.0" rpy="0.0 0.0 0.0"/>
  </joint>
  <link name="right_shoulder_gear_drive">
    <inertial>
      <origin xyz="-2.34906e-15 -1.16262e-15 -0.00662386" rpy="1.5708 -1.5708 0.0"/>
      <mass value="0.004"/>
      <inertia ixx="2.87762e-07" iyy="1.9527e-07" izz="1.9527e-07" ixy="0" ixz="0" iyz="0"/>
    </inertial>
    <visual name="right_shoulder_gear_drive_visual">
      <origin xyz="-2.34906e-15 -1.16573e-15 -0.00662386" rpy="-3.193e-13 -6.5592e-13 8.83086e-14"/>
      <geometry>
        <mesh filename="assets/right_shoulder_gear_drive_visual.stl" scale="1.0 1.0 1.0"/>
      </geometry>
      <material name="shoulder_gear_drive_visual_material"/>
    </visual>
  </link>
  <link name="right_shoulder_yaw_drive_body">
    <inertial>
      <origin xyz="0.0 0.0 0.0" rpy="0.0 0.0 0.0"/>
      <mass value="0.001"/>
      <inertia ixx="1e-09" iyy="1e-09" izz="1e-09" ixy="0" ixz="0" iyz="0"/>
    </inertial>
  </link>
  <joint type="fixed" name="right_shoulder_yaw_drive">
    <parent link="right_shoulder_roll_link"/>
    <child link="right_shoulder_yaw_drive_body"/>
    <origin xyz="-0.019 -0.024 -0.019" rpy="0.0 0.0 0.0"/>
  </joint>
  <joint type="fixed" name="right_shoulder_yaw_drive_offset">
    <parent link="right_shoulder_yaw_drive_body"/>
    <child link="right_shoulder_gear_drive"/>
    <origin xyz="0.0 0.0 0.0" rpy="0.0 0.0 0.0"/>
  </joint>
  <link name="right_shoulder_yaw_link">
    <inertial>
      <origin xyz="-3.5508000000000004e-18 -1.41456e-16 -0.0257843" rpy="0.0 0.0 1.5708"/>
      <mass value="0.0247439"/>
      <inertia ixx="1.54061e-05" iyy="1.01507e-05" izz="6.98599e-06" ixy="0" ixz="0" iyz="0"/>
    </inertial>
    <visual name="right_shoulder_yaw_link_visual">
      <origin xyz="-3.73574e-18 -1.38778e-16 -0.0257843" rpy="1.95123e-13 -4.7784e-13 -2.18896e-14"/>
      <geometry>
        <mesh filename="assets/right_shoulder_yaw_link_visual.stl" scale="1.0 1.0 1.0"/>
      </geometry>
      <material name="shoulder_yaw_link_visual_material"/>
    </visual>
    <collision name="right_shoulder_yaw_link_collision">
      <origin xyz="0.0 0.0 -0.04425" rpy="1.95123e-13 -4.7784e-13 -2.18896e-14"/>
      <geometry>
        <box type="box" size="0.046 0.025985 0.054214"/>
      </geometry>
    </collision>
  </link>
  <link name="right_shoulder_yaw_driven_body">
    <inertial>
      <origin xyz="0.0 0.0 0.0" rpy="0.0 0.0 0.0"/>
      <mass value="0.001"/>
      <inertia ixx="1e-09" iyy="1e-09" izz="1e-09" ixy="0" ixz="0" iyz="0"/>
    </inertial>
  </link>
  <joint type="revolute" name="right_shoulder_yaw_driven">
    <parent link="right_shoulder_roll_link"/>
    <child link="right_shoulder_yaw_driven_body"/>
    <origin xyz="-0.019 -3.58104e-10 -0.025" rpy="0.0 0.0 0.0"/>
    <axis xyz="0.0 0.0 -1.0"/>
    <limit lower="-3.1415926535897714" upper="3.141592653589815" effort="100" velocity="100"/>
  </joint>
  <joint type="fixed" name="right_shoulder_yaw_driven_offset">
    <parent link="right_shoulder_yaw_driven_body"/>
    <child link="right_shoulder_yaw_link"/>
    <origin xyz="0.0 0.0 0.0" rpy="0.0 0.0 0.0"/>
  </joint>
  <link name="right_elbow_roll_link">
    <inertial>
      <origin xyz="-0.0185402 -0.0117736 -0.00203648" rpy="1.58439 -1.33056 1.65059"/>
      <mass value="0.1152"/>
      <inertia ixx="3.485900290216656e-05" iyy="3.210267524717292e-05" izz="2.6556321850660507e-05" ixy="0" ixz="0" iyz="0"/>
    </inertial>
    <visual name="right_elbow_roll_link_visual">
      <origin xyz="-0.0185402 -0.0117736 -0.00203648" rpy="0.0 0.0 0.0"/>
      <geometry>
        <mesh filename="assets/right_elbow_roll_link_visual.stl" scale="1.0 1.0 1.0"/>
      </geometry>
      <material name="elbow_roll_link_visual_material"/>
    </visual>
    <collision name="right_elbow_roll_link_collision">
      <origin xyz="-0.01855 -0.012 -0.003" rpy="0.0 0.0 0.0"/>
      <geometry>
        <box type="box" size="0.0409 0.0465 0.046"/>
      </geometry>
    </collision>
  </link>
  <link name="right_elbow_roll_body">
    <inertial>
      <origin xyz="0.0 0.0 0.0" rpy="0.0 0.0 0.0"/>
      <mass value="0.001"/>
      <inertia ixx="1e-09" iyy="1e-09" izz="1e-09" ixy="0" ixz="0" iyz="0"/>
    </inertial>
  </link>
  <joint type="revolute" name="right_elbow_roll">
    <parent link="right_shoulder_yaw_link"/>
    <child link="right_elbow_roll_body"/>
    <origin xyz="0.019 -6.245e-17 -0.061" rpy="0.0 0.0 0.0"/>
    <axis xyz="-1.0 0.0 0.0"/>
    <limit lower="-2.268928027592629" upper="1.919862177193762" effort="100" velocity="100"/>
  </joint>
  <joint type="fixed" name="right_elbow_roll_offset">
    <parent link="right_elbow_roll_body"/>
    <child link="right_elbow_roll_link"/>
    <origin xyz="0.0 0.0 0.0" rpy="0.0 0.0 0.0"/>
  </joint>
  <link name="right_elbow_gear_drive">
    <inertial>
      <origin xyz="2.34906e-15 1.16429e-15 -0.00662386" rpy="1.5708 -1.5708 0.0"/>
      <mass value="0.004"/>
      <inertia ixx="2.87762e-07" iyy="1.9527e-07" izz="1.9527e-07" ixy="0" ixz="0" iyz="0"/>
    </inertial>
    <visual name="right_elbow_gear_drive_visual">
      <origin xyz="2.34906e-15 1.16573e-15 -0.00662386" rpy="1.90927e-13 -5.17586e-13 4.7224e-14"/>
      <geometry>
        <mesh filename="assets/right_elbow_gear_drive_visual.stl" scale="1.0 1.0 1.0"/>
      </geometry>
      <material name="elbow_gear_drive_visual_material"/>
    </visual>
  </link>
  <link name="right_elbow_yaw_drive_body">
    <inertial>
      <origin xyz="0.0 0.0 0.0" rpy="0.0 0.0 0.0"/>
      <mass value="0.001"/>
      <inertia ixx="1e-09" iyy="1e-09" izz="1e-09" ixy="0" ixz="0" iyz="0"/>
    </inertial>
  </link>
  <joint type="fixed" name="right_elbow_yaw_drive">
    <parent link="right_elbow_roll_link"/>
    <child link="right_elbow_yaw_drive_body"/>
    <origin xyz="-0.019 -0.024 -0.019" rpy="0.0 0.0 0.0"/>
  </joint>
  <joint type="fixed" name="right_elbow_yaw_drive_offset">
    <parent link="right_elbow_yaw_drive_body"/>
    <child link="right_elbow_gear_drive"/>
    <origin xyz="0.0 0.0 0.0" rpy="0.0 0.0 0.0"/>
  </joint>
  <link name="right_elbow_yaw_link">
    <inertial>
      <origin xyz="-2.3429e-12 -0.00604452 -0.0333598" rpy="0.600986 0.0 0.0"/>
      <mass value="0.0295299"/>
      <inertia ixx="2.81941e-05" iyy="1.8819699946116415e-05" izz="1.146310005388359e-05" ixy="0" ixz="0" iyz="0"/>
    </inertial>
    <visual name="right_elbow_yaw_link_visual">
      <origin xyz="-2.3429e-12 -0.00604452 -0.0333598" rpy="4.95938e-13 -1.54099e-13 -2.2543e-13"/>
      <geometry>
        <mesh filename="assets/right_elbow_yaw_link_visual.stl" scale="1.0 1.0 1.0"/>
      </geometry>
      <material name="elbow_yaw_link_visual_material"/>
    </visual>
    <collision name="right_elbow_yaw_link_collision">
      <origin xyz="0.0 -0.00335 -0.04475" rpy="4.95938e-13 -1.54099e-13 -2.2543e-13"/>
      <geometry>
        <box type="box" size="0.025985 0.0593 0.055126"/>
      </geometry>
    </collision>
  </link>
  <link name="right_elbow_yaw_driven_body">
    <inertial>
      <origin xyz="0.0 0.0 0.0" rpy="0.0 0.0 0.0"/>
      <mass value="0.001"/>
      <inertia ixx="1e-09" iyy="1e-09" izz="1e-09" ixy="0" ixz="0" iyz="0"/>
    </inertial>
  </link>
  <joint type="revolute" name="right_elbow_yaw_driven">
    <parent link="right_elbow_roll_link"/>
    <child link="right_elbow_yaw_driven_body"/>
    <origin xyz="-0.019 -3.58087e-10 -0.025" rpy="0.0 0.0 0.0"/>
    <axis xyz="0.0 0.0 -1.0"/>
    <limit lower="-3.141592653589588" upper="3.1415926535899983" effort="100" velocity="100"/>
  </joint>
  <joint type="fixed" name="right_elbow_yaw_driven_offset">
    <parent link="right_elbow_yaw_driven_body"/>
    <child link="right_elbow_yaw_link"/>
    <origin xyz="0.0 0.0 0.0" rpy="0.0 0.0 0.0"/>
  </joint>
  <link name="right_wrist_pitch_link">
    <inertial>
      <origin xyz="0.000415054 0.021867 0.0114965" rpy="1.49727 -0.0905553 1.57074"/>
      <mass value="0.1276"/>
      <inertia ixx="4.163705409382504e-05" iyy="3.5702593704251416e-05" izz="3.2970352201923534e-05" ixy="0" ixz="0" iyz="0"/>
    </inertial>
    <visual name="right_wrist_pitch_link_visual">
      <origin xyz="0.000415054 0.021867 0.0114965" rpy="0.0 0.0 0.0"/>
      <geometry>
        <mesh filename="assets/right_wrist_pitch_link_visual.stl" scale="1.0 1.0 1.0"/>
      </geometry>
      <material name="wrist_pitch_link_visual_material"/>
    </visual>
    <collision name="right_wrist_pitch_link_collision">
      <origin xyz="0.00045 0.0215 0.012" rpy="0.0 0.0 0.0"/>
      <geometry>
        <box type="box" size="0.0409 0.045 0.0465"/>
      </geometry>
    </collision>
  </link>
  <link name="right_wrist_pitch_driven_body">
    <inertial>
      <origin xyz="0.0 0.0 0.0" rpy="0.0 0.0 0.0"/>
      <mass value="0.001"/>
      <inertia ixx="1e-09" iyy="1e-09" izz="1e-09" ixy="0" ixz="0" iyz="0"/>
    </inertial>
  </link>
  <joint type="revolute" name="right_wrist_pitch_driven">
    <parent link="right_elbow_yaw_link"/>
    <child link="right_wrist_pitch_driven_body"/>
    <origin xyz="1.47538e-15 -0.022 -0.061" rpy="0.0 0.0 0.0"/>
    <axis xyz="0.0 1.0 0.0"/>
    <limit lower="-2.0943951023930585" upper="2.094395102393332" effort="100" velocity="100"/>
  </joint>
  <joint type="fixed" name="right_wrist_pitch_driven_offset">
    <parent link="right_wrist_pitch_driven_body"/>
    <child link="right_wrist_pitch_link"/>
    <origin xyz="0.0 0.0 0.0" rpy="0.0 0.0 0.0"/>
  </joint>
  <link name="right_wrist_gear_drive">
    <inertial>
      <origin xyz="2.90543e-16 -0.00503438 -3.98028e-15" rpy="1.5708 -1.5708 0.0"/>
      <mass value="0.003"/>
      <inertia ixx="2.24433e-07" iyy="1.33264e-07" izz="1.33264e-07" ixy="0" ixz="0" iyz="0"/>
    </inertial>
    <visual name="right_wrist_gear_drive_visual">
      <origin xyz="2.90543e-16 -0.00503438 -3.97788e-15" rpy="7.73714e-13 -5.77316e-13 -2.25636e-13"/>
      <geometry>
        <mesh filename="assets/right_wrist_gear_drive_visual.stl" scale="1.0 1.0 1.0"/>
      </geometry>
      <material name="wrist_gear_drive_visual_material"/>
    </visual>
  </link>
  <link name="right_wrist_pitch_drive_body">
    <inertial>
      <origin xyz="0.0 0.0 0.0" rpy="0.0 0.0 0.0"/>
      <mass value="0.001"/>
      <inertia ixx="1e-09" iyy="1e-09" izz="1e-09" ixy="0" ixz="0" iyz="0"/>
    </inertial>
  </link>
  <joint type="fixed" name="right_wrist_pitch_drive">
    <parent link="right_wrist_pitch_link"/>
    <child link="right_wrist_pitch_drive_body"/>
    <origin xyz="-1.52465e-10 0.003 0.024" rpy="0.0 0.0 0.0"/>
  </joint>
  <joint type="fixed" name="right_wrist_pitch_drive_offset">
    <parent link="right_wrist_pitch_drive_body"/>
    <child link="right_wrist_gear_drive"/>
    <origin xyz="0.0 0.0 0.0" rpy="0.0 0.0 0.0"/>
  </joint>
  <link name="right_gripper_link">
    <inertial>
      <origin xyz="-0.0327167 -0.0037537 -0.0303168" rpy="-0.187547 0.128059 1.22347"/>
      <mass value="0.0687174"/>
      <inertia ixx="5.5165857065345816e-05" iyy="5.3829164925713544e-05" izz="1.5607478008940635e-05" ixy="0" ixz="0" iyz="0"/>
    </inertial>
    <visual name="right_gripper_link_visual">
      <origin xyz="-0.0327167 -0.0037537 -0.0303168" rpy="0.0 0.0 0.0"/>
      <geometry>
        <mesh filename="assets/right_gripper_link_visual.stl" scale="1.0 1.0 1.0"/>
      </geometry>
      <material name="gripper_link_visual_material"/>
    </visual>
    <collision name="right_gripper_link_collision">
      <origin xyz="-0.019 -0.002925 -0.02885" rpy="0.0 0.0 0.0"/>
      <geometry>
        <box type="box" size="0.09 0.04935 0.0363"/>
      </geometry>
    </collision>
  </link>
  <link name="right_wrist_roll_body">
    <inertial>
      <origin xyz="0.0 0.0 0.0" rpy="0.0 0.0 0.0"/>
      <mass value="0.001"/>
      <inertia ixx="1e-09" iyy="1e-09" izz="1e-09" ixy="0" ixz="0" iyz="0"/>
    </inertial>
  </link>
  <joint type="revolute" name="right_wrist_roll">
    <parent link="right_wrist_pitch_link"/>
    <child link="right_wrist_roll_body"/>
    <origin xyz="0.019 0.022 -3.58073e-10" rpy="0.0 0.0 0.0"/>
    <axis xyz="1.0 0.0 0.0"/>
    <limit lower="-1.5707963267948966" upper="1.5707963267948966" effort="100" velocity="100"/>
  </joint>
  <joint type="fixed" name="right_wrist_roll_offset">
    <parent link="right_wrist_roll_body"/>
    <child link="right_gripper_link"/>
    <origin xyz="0.0 0.0 0.0" rpy="0.0 0.0 0.0"/>
  </joint>
  <link name="right_gripper_gear_drive">
    <inertial>
      <origin xyz="-3.1225e-17 3.21537e-17 -0.0025" rpy="1.5708 -1.5708 0.0"/>
      <mass value="0.00107037"/>
      <inertia ixx="5.01899e-08" iyy="2.73249e-08" izz="2.73249e-08" ixy="0" ixz="0" iyz="0"/>
    </inertial>
    <visual name="right_gripper_gear_drive_visual">
      <origin xyz="-3.1225e-17 3.1225e-17 -0.0025" rpy="0.0 0.0 -2.13163e-13"/>
      <geometry>
        <mesh filename="assets/right_gripper_gear_drive_visual.stl" scale="1.0 1.0 1.0"/>
      </geometry>
      <material name="gripper_gear_drive_visual_material"/>
    </visual>
  </link>
  <link name="right_gripper_rack_body">
    <inertial>
      <origin xyz="0.0 0.0 0.0" rpy="0.0 0.0 0.0"/>
      <mass value="0.001"/>
      <inertia ixx="1e-09" iyy="1e-09" izz="1e-09" ixy="0" ixz="0" iyz="0"/>
    </inertial>
  </link>
  <joint type="fixed" name="right_gripper_rack">
    <parent link="right_gripper_link"/>
    <child link="right_gripper_rack_body"/>
    <origin xyz="-0.04995 -0.0001 -0.0397" rpy="0.0 0.0 0.0"/>
  </joint>
  <joint type="fixed" name="right_gripper_rack_offset">
    <parent link="right_gripper_rack_body"/>
    <child link="right_gripper_gear_drive"/>
    <origin xyz="0.0 0.0 0.0" rpy="0.0 0.0 0.0"/>
  </joint>
  <link name="right_gripper_finger">
    <inertial>
      <origin xyz="0.00981816 0.0160522 -0.0386855" rpy="1.47162 -1.54237 0.116783"/>
      <mass value="0.0265733"/>
      <inertia ixx="1.2681950190120397e-05" iyy="1.0313366970303894e-05" izz="5.642052839575708e-06" ixy="0" ixz="0" iyz="0"/>
    </inertial>
    <visual name="right_gripper_finger_visual">
      <origin xyz="0.00981816 0.0160522 -0.0386855" rpy="-4.44089e-16 -2.66454e-15 1.77636e-15"/>
      <geometry>
        <mesh filename="assets/right_gripper_finger_visual.stl" scale="1.0 1.0 1.0"/>
      </geometry>
      <material name="gripper_finger_visual_material"/>
    </visual>
    <collision name="right_gripper_finger_collision_0">
      <origin xyz="0.0045 0.016125 -0.027" rpy="-4.44089e-16 -2.66454e-15 1.77636e-15"/>
      <geometry>
        <box type="box" size="0.009 0.0407 0.038"/>
      </geometry>
    </collision>
    <collision name="right_gripper_finger_collision_1">
      <origin xyz="0.01075 0.016125 -0.055" rpy="-4.44089e-16 -2.66454e-15 1.77636e-15"/>
      <geometry>
        <box type="box" size="0.0215 0.0407 0.018"/>
      </geometry>
    </collision>
  </link>
  <link name="right_gripper_pinion_body">
    <inertial>
      <origin xyz="0.0 0.0 0.0" rpy="0.0 0.0 0.0"/>
      <mass value="0.001"/>
      <inertia ixx="1e-09" iyy="1e-09" izz="1e-09" ixy="0" ixz="0" iyz="0"/>
    </inertial>
  </link>
  <joint type="prismatic" name="right_gripper_pinion">
    <parent link="right_gripper_link"/>
    <child link="right_gripper_pinion_body"/>
    <origin xyz="-0.064 -0.015975 -0.03985" rpy="0.0 0.0 0.0"/>
    <axis xyz="1.0 0.0 0.0"/>
    <limit lower="-0.000872999999993866" upper="0.023500000000006134" effort="100" velocity="100"/>
  </joint>
  <joint type="fixed" name="right_gripper_pinion_offset">
    <parent link="right_gripper_pinion_body"/>
    <child link="right_gripper_finger"/>
    <origin xyz="0.0 0.0 0.0" rpy="0.0 0.0 0.0"/>
  </joint>
  <link name="right_gripper_finger_2">
    <inertial>
      <origin xyz="-0.00981816 -0.0160522 -0.0386855" rpy="1.47162 -1.54237 0.116783"/>
      <mass value="0.0265733"/>
      <inertia ixx="1.2681950190120397e-05" iyy="1.0313366970303894e-05" izz="5.642052839575708e-06" ixy="0" ixz="0" iyz="0"/>
    </inertial>
    <visual name="right_gripper_finger_2_visual">
      <origin xyz="-0.00981816 -0.0160522 -0.0386855" rpy="5.55112e-17 0.0 -2.77556e-16"/>
      <geometry>
        <mesh filename="assets/right_gripper_finger_2_visual.stl" scale="1.0 1.0 1.0"/>
      </geometry>
      <material name="gripper_finger_2_visual_material"/>
    </visual>
    <collision name="right_gripper_finger_2_collision_0">
      <origin xyz="-0.0045 -0.016125 -0.027" rpy="5.55112e-17 0.0 -2.77556e-16"/>
      <geometry>
        <box type="box" size="0.009 0.0407 0.038"/>
      </geometry>
    </collision>
    <collision name="right_gripper_finger_2_collision_1">
      <origin xyz="-0.01075 -0.016125 -0.055" rpy="5.55112e-17 0.0 -2.77556e-16"/>
      <geometry>
        <box type="box" size="0.0215 0.0407 0.018"/>
      </geometry>
    </collision>
  </link>
  <link name="right_gripper_pinion_mirror_body">
    <inertial>
      <origin xyz="0.0 0.0 0.0" rpy="0.0 0.0 0.0"/>
      <mass value="0.001"/>
      <inertia ixx="1e-09" iyy="1e-09" izz="1e-09" ixy="0" ixz="0" iyz="0"/>
    </inertial>
  </link>
  <joint type="prismatic" name="right_gripper_pinion_mirror">
    <parent link="right_gripper_link"/>
    <child link="right_gripper_pinion_mirror_body"/>
    <origin xyz="0.026 0.015975 -0.03985" rpy="0.0 0.0 0.0"/>
    <axis xyz="-1.0 0.0 0.0"/>
    <limit lower="-0.000873000000007036" upper="0.023499999999992964" effort="100" velocity="100"/>
    <mimic joint="right_gripper_pinion" multiplier="1" offset="0"/>
  </joint>
  <joint type="fixed" name="right_gripper_pinion_mirror_offset">
    <parent link="right_gripper_pinion_mirror_body"/>
    <child link="right_gripper_finger_2"/>
    <origin xyz="0.0 0.0 0.0" rpy="0.0 0.0 0.0"/>
  </joint>
  <material name="ankle_pitch_link_visual_material">
    <color rgba="0.708413 0.627926 0.367392 1"/>
  </material>
  <material name="ankle_roll_link_visual_material">
    <color rgba="0.615686 0.811765 0.929412 1"/>
  </material>
  <material name="elbow_gear_drive_visual_material">
    <color rgba="0.615686 0.811765 0.929412 1"/>
  </material>
  <material name="elbow_roll_link_visual_material">
    <color rgba="0.75922 0.862174 0.917756 1"/>
  </material>
  <material name="elbow_yaw_link_visual_material">
    <color rgba="0.516885 0.653641 0.793594 1"/>
  </material>
  <material name="gripper_finger_2_visual_material">
    <color rgba="0.615686 0.811765 0.929412 1"/>
  </material>
  <material name="gripper_finger_visual_material">
    <color rgba="0.615686 0.811765 0.929412 1"/>
  </material>
  <material name="gripper_gear_drive_visual_material">
    <color rgba="0.647059 0.647059 0.647059 1"/>
  </material>
  <material name="gripper_link_visual_material">
    <color rgba="0.630539 0.762991 0.810843 1"/>
  </material>
  <material name="head_visual_material">
    <color rgba="0.628184 0.794414 0.875689 1"/>
  </material>
  <material name="hip_pitch_link_visual_material">
    <color rgba="0.940459 0.715563 0.0942225 1"/>
  </material>
  <material name="hip_roll_link_visual_material">
    <color rgba="0.615686 0.811765 0.929412 1"/>
  </material>
  <material name="hip_yaw_gear_drive_visual_material">
    <color rgba="0.615686 0.811765 0.929412 1"/>
  </material>
  <material name="hip_yaw_link_visual_material">
    <color rgba="0.801331 0.729185 0.393273 1"/>
  </material>
  <material name="knee_link_visual_material">
    <color rgba="0.615686 0.811765 0.929412 1"/>
  </material>
  <material name="neck_pitch_plate_visual_material">
    <color rgba="0.647059 0.647059 0.647059 1"/>
  </material>
  <material name="neck_rod_2_visual_material">
    <color rgba="0.62596 0.757827 0.836947 1"/>
  </material>
  <material name="neck_rod_visual_material">
    <color rgba="0.62596 0.757827 0.836947 1"/>
  </material>
  <material name="neck_yaw_gear_drive_visual_material">
    <color rgba="0.647059 0.647059 0.647059 1"/>
  </material>
  <material name="neck_yaw_link_visual_material">
    <color rgba="0.231373 0.380392 0.705882 1"/>
  </material>
  <material name="pelvis_link_visual_material">
    <color rgba="0.642812 0.76997 0.800997 1"/>
  </material>
  <material name="shoulder_gear_drive_visual_material">
    <color rgba="0.615686 0.811765 0.929412 1"/>
  </material>
  <material name="shoulder_pitch_link_visual_material">
    <color rgba="0.615686 0.811765 0.929412 1"/>
  </material>
  <material name="shoulder_roll_link_visual_material">
    <color rgba="0.75922 0.862174 0.917756 1"/>
  </material>
  <material name="shoulder_yaw_link_visual_material">
    <color rgba="0.542005 0.729062 0.886557 1"/>
  </material>
  <material name="torso_visual_material">
    <color rgba="0.63539 0.796011 0.905481 1"/>
  </material>
  <material name="waist_gear_drive_2_visual_material">
    <color rgba="0.647059 0.647059 0.647059 1"/>
  </material>
  <material name="waist_gear_drive_visual_material">
    <color rgba="0.647059 0.647059 0.647059 1"/>
  </material>
  <material name="waist_gears_visual_material">
    <color rgba="0.307262 0.428048 0.687761 1"/>
  </material>
  <material name="wrist_gear_drive_visual_material">
    <color rgba="0.615686 0.811765 0.929412 1"/>
  </material>
  <material name="wrist_pitch_link_visual_material">
    <color rgba="0.748702 0.84202 0.892409 1"/>
  </material>
</robot>