<?xml version="1.0" ?>
<mujoco model="toddlerbot_2xm_gripper">
  <compiler angle="radian" meshdir="assets" autolimits="true"/>
  <default class="main">
    <geom condim="1" contype="0" conaffinity="0"/>
    <joint damping="0.01" armature="0.0" frictionloss="0.01"/>
    <default class="visual">
      <geom group="2" density="0"/>
    </default>
    <default class="collision">
      <geom group="3"/>
    </default>
    <default class="XC330">
      <joint damping="0.001" armature="0.0048" frictionloss="0.006"/>
    </default>
    <default class="XC430">
      <joint damping="0.0072" armature="0.0044" frictionloss="0.014"/>
    </default>
    <default class="XM430-W350">
      <joint damping="0.0133" armature="0.0025" frictionloss="0.105"/>
    </default>
    <default class="XM430-W210">
      <joint damping="0.0064" armature="0.0022" frictionloss="0.038"/>
    </default>
    <default class="2XL430">
      <joint damping="0.0013" armature="0.0083" frictionloss="0.069"/>
    </default>
    <default class="2XC430">
      <joint damping="0.0028" armature="0.0044" frictionloss="0.06"/>
    </default>
    <motor ctrlrange="-10 10"/>
  </default>
  <worldbody>
    <geom type="mesh" class="visual" pos="-0.0194013 -0.00385148 0.0614411" quat="1.0 0.0 0.0 0.0" mesh="torso_visual" material="torso_visual_material"/>
    <geom type="box" class="collision" pos="-0.025508 0.0 0.06" quat="1.0 0.0 0.0 0.0" size="0.045 0.065 0.06" name="torso_collision_0" material="torso_visual_material"/>
    <geom type="box" class="collision" pos="-0.093008 0.0 0.01425" quat="1.0 0.0 0.0 0.0" size="0.0225 0.01425 0.01425" name="torso_collision_1" material="torso_visual_material"/>
    <body name="neck_yaw_gear_drive" pos="-0.0215079 1.21496e-14 0.119" quat="1 0 0 0">
      <joint axis="0.0 0.0 -1.0" name="neck_yaw_drive" type="hinge" range="-2.8797932657906435 2.8797932657906435" class="XC330"/>
      <inertial pos="8.2581e-17 1.36534e-15 0.0033841" mass="0.003" fullinertia="8.71388e-08 8.71388e-08 1.55295e-07 -1.17518e-38 -6.43333e-37 -1.88743e-36"/>
      <geom type="mesh" class="visual" pos="8.38906e-17 1.36534e-15 0.0033841" quat="1.0 0.0 0.0 0.0" mesh="neck_yaw_gear_drive_visual" material="neck_yaw_gear_drive_visual_material"/>
    </body>
    <body name="neck_yaw_link" pos="-0.00050787 -1.1277e-19 0.124" quat="1 0 0 0">
      <joint axis="0.0 0.0 1.0" name="neck_yaw_driven" type="hinge" range="-2.6179938779914944 2.6179938779914944"/>
      <inertial pos="-3.4067e-06 -1.86e-09 0.00821562" mass="0.006" fullinertia="4.77698e-07 6.2064e-07 3.29073e-07 -3.8855e-15 2.24356e-09 -2.43334e-14"/>
      <geom type="mesh" class="visual" pos="-3.4067e-06 -1.86e-09 0.00821562" quat="1.0 -3.4030000000000003e-18 5.4817e-16 1.11654e-16" mesh="neck_yaw_link_visual" material="neck_yaw_link_visual_material"/>
      <site group="3" name="closing_neck_pitch_front_2" pos="0.00724444 -0.004 0.0169411" quat="1.87916e-15 -2.4484e-15 -0.707107 -0.707107"/>
      <site group="3" name="closing_neck_pitch_front_2_z" pos="0.00724444 0.096 0.0169411" quat="1.87916e-15 -2.4484e-15 -0.707107 -0.707107"/>
      <site group="3" name="closing_neck_pitch_back_2" pos="-0.00724444 -0.004 0.0130589" quat="1.87916e-15 -2.4484e-15 -0.707107 -0.707107"/>
      <site group="3" name="closing_neck_pitch_back_2_z" pos="-0.00724444 0.096 0.0130589" quat="1.87916e-15 -2.4484e-15 -0.707107 -0.707107"/>
      <body name="head" pos="9.24195e-17 0.004 0.015" quat="1 0 0 0">
        <joint axis="0.0 1.0 0.0" name="neck_pitch" type="hinge" range="-0.6108652381980295 1.3962634015954494"/>
        <inertial pos="-0.0104852 0.00111009 0.0447856" mass="0.143321" fullinertia="0.000108706 0.00012191 9.64039e-05 9.11996e-07 1.06384e-05 -1.64047e-06"/>
        <geom type="mesh" class="visual" pos="-0.0104852 0.00111009 0.0447856" quat="1.0 2.22045e-16 3.93183e-16 7.0813e-17" mesh="head_visual" material="head_visual_material"/>
        <geom type="box" class="collision" pos="-0.0105 -0.0035 0.046416" quat="1.0 2.22045e-16 3.93183e-16 7.0813e-17" size="0.035 0.042 0.03" name="head_collision" material="head_visual_material"/>
        <body name="neck_pitch_plate" pos="-0.027 -0.0025 0.0326157" quat="1 0 0 0">
          <joint axis="0.0 -1.0 0.0" name="neck_pitch_act" type="hinge" range="-0.6108652381980046 1.3962634015954742" class="XC330"/>
          <inertial pos="-1.80633e-16 -0.00282818 6.9349e-16" mass="0.002" fullinertia="6.09113e-08 5.6539e-08 1.08464e-07 1.28339e-09 -2.05478e-36 -6.25053e-36"/>
          <geom type="mesh" class="visual" pos="-1.82311e-16 -0.00282818 6.90937e-16" quat="1.0 -1.22125e-13 3.58315e-16 1.05919e-16" mesh="neck_pitch_plate_visual" material="neck_pitch_plate_visual_material"/>
          <body name="neck_rod" pos="0.00723736 -0.0055 0.0019674" quat="1 0 0 0">
            <joint axis="0.0 -1.0 0.0" name="neck_pitch_front" type="hinge" range="-18.491769236552884 6.6409719921654595"/>
            <inertial pos="0.0135129 -0.00159086 -0.0162914" mass="0.00297389" fullinertia="9.56037e-07 1.7273e-08 9.68779e-07 -7.99108e-10 1.54025e-12 9.94055e-13"/>
            <geom type="mesh" class="visual" pos="0.0135129 -0.00159086 -0.0162914" quat="-1.0 -1.97758e-15 -2.3203e-07 -8.32667e-17" mesh="neck_rod_visual" material="neck_rod_visual_material"/>
            <site group="3" name="closing_neck_pitch_front_1" pos="0.0270071 3.58114e-15 -0.032642" quat="0.300467 -0.300467 -0.640093 -0.640093"/>
            <site group="3" name="closing_neck_pitch_front_1_z" pos="0.0270071 0.1 -0.032642" quat="0.300467 -0.300467 -0.640093 -0.640093"/>
          </body>
          <body name="neck_rod_2" pos="-0.00723736 -0.0055 -0.0019674" quat="1 0 0 0">
            <joint axis="0.0 -1.0 0.0" name="neck_pitch_back" type="hinge" range="-12.2096530466637 12.923088182054645"/>
            <inertial pos="0.0135222 -0.00159086 -0.0162731" mass="0.00297389" fullinertia="9.55015e-07 1.72746e-08 9.67759e-07 -1.0303e-09 -1.98975e-12 -8.21497e-15"/>
            <geom type="mesh" class="visual" pos="0.0135222 -0.00159086 -0.0162731" quat="1.0 -1.22506e-13 4.2258e-07 -3.25295e-14" mesh="neck_rod_2_visual" material="neck_rod_2_visual_material"/>
            <site group="3" name="closing_neck_pitch_back_1" pos="0.0269929 3.81189e-15 -0.0325894" quat="-0.300126 0.300126 0.640254 0.640254"/>
            <site group="3" name="closing_neck_pitch_back_1_z" pos="0.0269929 0.1 -0.0325894" quat="-0.300126 0.300126 0.640254 0.640254"/>
          </body>
        </body>
      </body>
    </body>
    <body name="waist_gears" pos="-0.0165079 -1.92151e-17 -0.00248651" quat="1 0 0 0">
      <joint axis="0.0 0.0 1.0" name="waist_yaw" type="hinge" range="-1.570796326794878 1.5707963267949152"/>
      <inertial pos="-2.81849e-10 1.55293e-09 -0.0129916" mass="0.0371617" fullinertia="2.6567e-06 1.19063e-05 1.15726e-05 4.54262e-13 -9.23141e-13 -1.27177e-12"/>
      <geom type="mesh" class="visual" pos="-2.81849e-10 1.55293e-09 -0.0129916" quat="1.0 -2.3302e-17 3.3404100000000006e-31 -5.174090000000001e-33" mesh="waist_gears_visual" material="waist_gears_visual_material"/>
      <body name="pelvis_link" pos="0.0230079 2.89995e-16 -0.014" quat="1 0 0 0">
        <joint axis="1.0 0.0 0.0" name="waist_roll" type="hinge" range="-0.5235987755983015 0.5235987755982962" damping="0.5" armature="0.002" frictionloss="0.03"/>
        <inertial pos="-0.0231545 1.60597e-15 -0.0260806" mass="0.1052" fullinertia="4.57052e-05 9.14349e-05 6.74285e-05 1.20054e-18 -5.62512e-09 4.46433e-07"/>
        <geom type="mesh" class="visual" pos="-0.0231545 1.60597e-15 -0.0260806" quat="1.0 -4.44089e-16 -2.22045e-16 -1.43774e-14" mesh="pelvis_link_visual" material="pelvis_link_visual_material"/>
        <geom type="box" class="collision" pos="-0.02275 6.22778e-16 -0.035346" quat="1.0 -4.44089e-16 -2.22045e-16 -1.43774e-14" size="0.035 0.06 0.022169" name="pelvis_link_collision" material="pelvis_link_visual_material"/>
        <body name="waist_gear_drive" pos="-0.01275 -1.71841e-16 -0.0196" quat="1 0 0 0">
          <joint axis="0.0 0.0 1.0" name="waist_act_1" type="hinge" range="-4.67748239534475 4.677482395344857" class="XC330"/>
          <inertial pos="3.70003e-10 -6.58783e-10 0.00671824" mass="0.002" fullinertia="3.70258e-08 3.70258e-08 3.95436e-08 -1.39638e-16 2.14499e-15 -3.4519e-16"/>
          <geom type="mesh" class="visual" pos="3.70003e-10 -6.58783e-10 0.00671824" quat="-1.0 1.78135e-15 4.16783e-16 4.11893e-14" mesh="waist_gear_drive_visual" material="waist_gear_drive_visual_material"/>
        </body>
        <body name="waist_gear_drive_2" pos="-0.03275 1.40567e-16 -0.0196" quat="1 0 0 0">
          <joint axis="0.0 0.0 1.0" name="waist_act_2" type="hinge" range="-4.677482395344769 4.677482395344838" class="XC330"/>
          <inertial pos="3.70003e-10 -6.58783e-10 0.00671824" mass="0.002" fullinertia="3.70258e-08 3.70258e-08 3.95436e-08 -1.39638e-16 2.14499e-15 -3.4519e-16"/>
          <geom type="mesh" class="visual" pos="3.70003e-10 -6.58783e-10 0.00671824" quat="-1.0 1.9032e-15 1.07998e-15 3.16414e-14" mesh="waist_gear_drive_2_visual" material="waist_gear_drive_2_visual_material"/>
        </body>
        <body name="left_hip_pitch_link" pos="-0.02275 0.018 -0.0481" quat="1 0 0 0">
          <joint axis="0.0 1.0 0.0" name="left_hip_pitch" type="hinge" range="-2.356194490192225 0.7853981633975682" class="XM430-W350"/>
          <inertial pos="-0.0203085 0.0188253 -0.0117862" mass="0.188221" fullinertia="5.02407e-05 0.000131412 0.000114387 6.67628e-07 3.4007e-07 3.52173e-08"/>
          <geom type="mesh" class="visual" pos="-0.0203085 0.0188253 -0.0117862" quat="-1.0 4.44089e-16 2.22045e-16 1.43774e-14" mesh="left_hip_pitch_link_visual" material="hip_pitch_link_visual_material"/>
          <geom type="box" class="collision" pos="-0.01805 0.0168 -0.012" quat="-1.0 4.44089e-16 2.22045e-16 1.43774e-14" size="0.04295 0.0212 0.02325" name="left_hip_pitch_link_collision" material="hip_pitch_link_visual_material"/>
          <body name="left_hip_roll_link" pos="-0.023 0.019 -0.024" quat="1 0 0 0">
            <joint axis="1.0 0.0 0.0" name="left_hip_roll" type="hinge" range="-0.7853981633975363 1.5707963267948084" class="XM430-W350"/>
            <inertial pos="0.0246449 -3.2234e-06 -0.0172318" mass="0.022" fullinertia="9.95174e-06 8.77725e-06 4.31095e-06 4.28756e-10 1.73581e-09 8.52448e-08"/>
            <geom type="mesh" class="visual" pos="0.0246449 -3.2234e-06 -0.0172318" quat="-1.0 4.44089e-16 2.22045e-16 1.44329e-14" mesh="left_hip_roll_link_visual" material="hip_roll_link_visual_material"/>
            <body name="left_hip_yaw_link" pos="0.023 -6.96693e-16 -0.033" quat="1 0 0 0">
              <joint axis="0.0 0.0 -1.0" name="left_hip_yaw_driven" type="hinge" range="-1.570796326794896 1.5707963267948972"/>
              <inertial pos="-0.00967359 0.00117184 -0.0353305" mass="0.159688" fullinertia="7.87703e-05 6.10529e-05 5.28311e-05 1.39999e-06 4.42417e-06 -4.14409e-06"/>
              <geom type="mesh" class="visual" pos="-0.00967359 0.00117184 -0.0353305" quat="-1.0 4.51108e-14 -5.77129e-15 1.44329e-14" mesh="left_hip_yaw_link_visual" material="hip_yaw_link_visual_material"/>
              <geom type="box" class="collision" pos="-0.009525 0.000575004 -0.031475" quat="-1.0 4.51108e-14 -5.77129e-15 1.44329e-14" size="0.029525 0.023975 0.031475" name="left_hip_yaw_link_collision" material="hip_yaw_link_visual_material"/>
              <body name="left_hip_yaw_gear_drive" pos="-0.0192 -0.0002 1.12946e-14" quat="1 0 0 0">
                <joint axis="0.0 0.0 1.0" name="left_hip_yaw_drive" type="hinge" range="-1.832595714594047 1.8325957145940452" class="XC330"/>
                <inertial pos="8.70043e-17 -3.26845e-16 0.00175" mass="0.001" fullinertia="2.46213e-08 2.46213e-08 4.7219e-08 -2.00946e-37 -7.65096e-37 1.36016e-36"/>
                <geom type="mesh" class="visual" pos="8.6489e-17 -3.24943e-16 0.00175" quat="1.0 -4.53657e-14 5.80343e-15 -6.56931e-14" mesh="left_hip_yaw_gear_drive_visual" material="hip_yaw_gear_drive_visual_material"/>
              </body>
              <body name="left_knee_link" pos="-4.78197e-16 -0.019 -0.0445" quat="1 0 0 0">
                <joint axis="0.0 -1.0 0.0" name="left_knee" type="hinge" range="-2.0943951023931953 0.0" class="XM430-W210"/>
                <inertial pos="0.00452332 0.019 -0.0505695" mass="0.029" fullinertia="5.21355e-05 1.29755e-05 4.23701e-05 -6.33017e-08 -2.20854e-34 -1.10716e-34"/>
                <geom type="mesh" class="visual" pos="0.00452332 0.019 -0.0505695" quat="-1.0 2.22045e-16 -5.62564e-15 -1.9441e-15" mesh="left_knee_link_visual" material="knee_link_visual_material"/>
                <geom type="box" class="collision" pos="4.99872e-09 0.019 -0.0511526" quat="-1.0 2.22045e-16 -5.62564e-15 -1.9441e-15" size="0.015 0.023 0.0661526" name="left_knee_link_collision" material="knee_link_visual_material"/>
                <body name="left_ankle_pitch_link" pos="-7.16755e-18 -4.83405e-17 -0.11" quat="1 0 0 0">
                  <joint axis="0.0 1.0 0.0" name="left_ankle_pitch" type="hinge" range="-1.8325957145940461 0.9599310885968813" class="XM430-W210"/>
                  <inertial pos="-0.0179692 0.0188074 0.0120892" mass="0.172721" fullinertia="4.63892e-05 0.000105456 0.000120422 -1.34515e-06 -5.71207e-07 -4.99723e-08"/>
                  <geom type="mesh" class="visual" pos="-0.0179692 0.0188074 0.0120892" quat="-1.0 3.33067e-16 -5.65904e-15 -1.9252e-15" mesh="left_ankle_pitch_link_visual" material="ankle_pitch_link_visual_material"/>
                  <geom type="box" class="collision" pos="-0.01855 0.0168 0.012" quat="-1.0 3.33067e-16 -5.65904e-15 -1.9252e-15" size="0.04345 0.0212 0.02325" name="left_ankle_pitch_link_collision" material="ankle_pitch_link_visual_material"/>
                  <body name="left_ankle_roll_link" pos="-0.023 0.019 1.74256e-14" quat="1 0 0 0">
                    <joint axis="1.0 0.0 0.0" name="left_ankle_roll" type="hinge" range="-1.221730476395942 1.2217304763961192" class="XC430"/>
                    <inertial pos="0.0358432 -6.70173e-08 -0.0267229" mass="0.039" fullinertia="2.88034e-05 3.04307e-05 8.87438e-06 6.52846e-11 2.12102e-06 2.65224e-10"/>
                    <geom type="mesh" class="visual" pos="0.0358432 -6.70173e-08 -0.0267229" quat="1.0 -5.42571e-16 2.44027e-13 1.89101e-15" mesh="left_ankle_roll_link_visual" material="ankle_roll_link_visual_material"/>
                    <geom type="mesh" class="collision" mesh="left_ankle_roll_link_collision" pos="0.0358432 -6.70173e-08 -0.0267229" quat="1.0 -5.42571e-16 2.44027e-13 1.89101e-15" name="left_ankle_roll_link_collision" material="ankle_roll_link_visual_material" contype="1" conaffinity="1"/>
                    <site name="left_foot_center" pos="0.0358432 -6.70173e-08 -0.0374345" type="sphere" size="0.005" rgba="0.9 0.1 0.1 0.8"/>
                  </body>
                </body>
              </body>
            </body>
          </body>
        </body>
        <body name="right_hip_pitch_link" pos="-0.02275 -0.018 -0.0481" quat="1 0 0 0">
          <joint axis="0.0 -1.0 0.0" name="right_hip_pitch" type="hinge" range="-0.7853981633974225 2.3561944901923706" class="XM430-W350"/>
          <inertial pos="-0.0202238 -0.0188253 -0.0117862" mass="0.188221" fullinertia="5.02407e-05 0.000130791 0.000113766 -6.64843e-07 3.37867e-07 -3.52173e-08"/>
          <geom type="mesh" class="visual" pos="-0.0202238 -0.0188253 -0.0117862" quat="1.0 -4.44089e-16 -2.22045e-16 -1.43774e-14" mesh="right_hip_pitch_link_visual" material="hip_pitch_link_visual_material"/>
          <geom type="box" class="collision" pos="-0.0179687 -0.0168 -0.012" quat="1.0 -4.44089e-16 -2.22045e-16 -1.43774e-14" size="0.0428688 0.0212 0.02325" name="right_hip_pitch_link_collision" material="hip_pitch_link_visual_material"/>
          <body name="right_hip_roll_link" pos="-0.0228375 -0.019 -0.024" quat="1 0 0 0">
            <joint axis="1.0 0.0 0.0" name="right_hip_roll" type="hinge" range="-1.5707963267948664 0.7853981633974785" class="XM430-W350"/>
            <inertial pos="0.0246449 -3.2234e-06 -0.0172318" mass="0.022" fullinertia="9.95174e-06 8.77725e-06 4.31095e-06 4.28756e-10 1.73581e-09 8.52448e-08"/>
            <geom type="mesh" class="visual" pos="0.0246449 -3.2234e-06 -0.0172318" quat="1.0 -4.44089e-16 -2.22045e-16 -1.44329e-14" mesh="right_hip_roll_link_visual" material="hip_roll_link_visual_material"/>
            <body name="right_hip_yaw_link" pos="0.023 -6.96693e-16 -0.033" quat="1 0 0 0">
              <joint axis="0.0 0.0 -1.0" name="right_hip_yaw_driven" type="hinge" range="-1.570796326794897 1.5707963267948961"/>
              <inertial pos="-0.00967257 -0.00117152 -0.0353303" mass="0.159688" fullinertia="7.87648e-05 6.10535e-05 5.28244e-05 -1.39863e-06 -4.42456e-06 -4.13719e-06"/>
              <geom type="mesh" class="visual" pos="-0.00967257 -0.00117152 -0.0353303" quat="-1.0 -1.4056e-14 4.72389e-15 1.54321e-14" mesh="right_hip_yaw_link_visual" material="hip_yaw_link_visual_material"/>
              <geom type="box" class="collision" pos="-0.009525 -0.000574999 -0.031475" quat="-1.0 -1.4056e-14 4.72389e-15 1.54321e-14" size="0.029525 0.023975 0.031475" name="right_hip_yaw_link_collision" material="hip_yaw_link_visual_material"/>
              <body name="right_hip_yaw_gear_drive" pos="-0.0192 0.0002 1.12316e-14" quat="1 0 0 0">
                <joint axis="0.0 0.0 1.0" name="right_hip_yaw_drive" type="hinge" range="-1.8325957145940457 1.8325957145940466" class="XC330"/>
                <inertial pos="-9.06167e-17 3.37738e-16 0.00175" mass="0.001" fullinertia="2.46213e-08 2.46213e-08 4.7219e-08 6.81072e-37 5.28571e-37 -3.38851e-37"/>
                <geom type="mesh" class="visual" pos="-9.16238e-17 3.37849e-16 0.00175" quat="1.0 1.40558e-14 -4.75887e-15 -8.29674e-14" mesh="right_hip_yaw_gear_drive_visual" material="hip_yaw_gear_drive_visual_material"/>
              </body>
              <body name="right_knee_link" pos="5.00205e-16 0.019 -0.0445" quat="1 0 0 0">
                <joint axis="0.0 1.0 0.0" name="right_knee" type="hinge" range="0.0 2.0943951023931953" class="XM430-W210"/>
                <inertial pos="0.00452332 -0.019 -0.0505695" mass="0.029" fullinertia="5.21355e-05 1.29755e-05 4.23701e-05 6.33017e-08 -8.41297e-36 1.78994e-34"/>
                <geom type="mesh" class="visual" pos="0.00452332 -0.019 -0.0505695" quat="1.0 -9.99201e-16 -7.67037e-17 -1.60344e-14" mesh="right_knee_link_visual" material="knee_link_visual_material"/>
                <geom type="box" class="collision" pos="4.99872e-09 -0.019 -0.0511526" quat="1.0 -9.99201e-16 -7.67037e-17 -1.60344e-14" size="0.015 0.023 0.0661526" name="right_knee_link_collision" material="knee_link_visual_material"/>
                <body name="right_ankle_pitch_link" pos="-1.14853e-17 -2.25611e-16 -0.11" quat="1 0 0 0">
                  <joint axis="0.0 -1.0 0.0" name="right_ankle_pitch" type="hinge" range="-0.9599310885968813 1.8325957145940461" class="XM430-W210"/>
                  <inertial pos="-0.0179692 -0.018812 0.0120892" mass="0.172721" fullinertia="4.63895e-05 0.000105456 0.000120422 1.34515e-06 6.10239e-07 -4.03833e-08"/>
                  <geom type="mesh" class="visual" pos="-0.0179692 -0.018812 0.0120892" quat="1.0 -2.77556e-16 -1.72238e-16 -1.61871e-14" mesh="right_ankle_pitch_link_visual" material="ankle_pitch_link_visual_material"/>
                  <geom type="box" class="collision" pos="-0.01855 -0.0168 0.012" quat="1.0 -2.77556e-16 -1.72238e-16 -1.61871e-14" size="0.04345 0.0212 0.02325" name="right_ankle_pitch_link_collision" material="ankle_pitch_link_visual_material"/>
                  <body name="right_ankle_roll_link" pos="-0.023 -0.019 1.78974e-14" quat="1 0 0 0">
                    <joint axis="1.0 0.0 0.0" name="right_ankle_roll" type="hinge" range="-1.221730476396059 1.2217304763960022" class="XC430"/>
                    <inertial pos="0.0358432 -6.70173e-08 -0.0267229" mass="0.039" fullinertia="2.88034e-05 3.04307e-05 8.87438e-06 6.52846e-11 2.12102e-06 2.65224e-10"/>
                    <geom type="mesh" class="visual" pos="0.0358432 -6.70173e-08 -0.0267229" quat="-1.0 4.82379e-16 -2.56073e-13 1.60263e-14" mesh="right_ankle_roll_link_visual" material="ankle_roll_link_visual_material"/>
                    <geom type="mesh" class="collision" mesh="right_ankle_roll_link_collision" pos="0.0358432 -6.70173e-08 -0.0267229" quat="-1.0 4.82379e-16 -2.56073e-13 1.60263e-14" name="right_ankle_roll_link_collision" material="ankle_roll_link_visual_material" contype="1" conaffinity="1"/>
                    <site name="right_foot_center" pos="0.0358432 -6.70173e-08 -0.0374345" type="sphere" size="0.005" rgba="0.9 0.1 0.1 0.8"/>
                  </body>
                </body>
              </body>
            </body>
          </body>
        </body>
      </body>
    </body>
    <body name="left_shoulder_pitch_link" pos="-0.0200079 0.067 0.10175" quat="1 0 0 0">
      <joint axis="0.0 1.0 0.0" name="left_shoulder_pitch" type="hinge" range="-3.1415926535897913 3.141592653589795" class="XC430"/>
      <inertial pos="1.99287e-19 0.0129132 6.38666e-18" mass="0.015" fullinertia="3.20331e-06 6.13264e-06 6.99606e-06 1.50289e-22 6.91007e-21 -5.72192e-19"/>
      <geom type="mesh" class="visual" pos="1.99287e-19 0.0129132 6.38666e-18" quat="1.0 1.0916500000000001e-30 1.56978e-16 -1.56978e-16" mesh="left_shoulder_pitch_link_visual" material="shoulder_pitch_link_visual_material"/>
      <body name="left_shoulder_roll_link" pos="-0.019 0.027 -1.67365e-15" quat="1 0 0 0">
        <joint axis="1.0 0.0 0.0" name="left_shoulder_roll" type="hinge" range="-0.43633231299806097 1.570796326795418" class="2XC430"/>
        <inertial pos="0.0185402 0.0117736 -0.00203648" mass="0.1152" fullinertia="2.66052e-05 3.22099e-05 3.47029e-05 -5.25219e-07 3.29206e-08 -6.36632e-07"/>
        <geom type="mesh" class="visual" pos="0.0185402 0.0117736 -0.00203648" quat="1.0 5.55112e-17 1.66533e-16 -1.66533e-16" mesh="left_shoulder_roll_link_visual" material="shoulder_roll_link_visual_material"/>
        <geom type="box" class="collision" pos="0.01855 0.012 -0.003" quat="1.0 5.55112e-17 1.66533e-16 -1.66533e-16" size="0.02045 0.02325 0.023" name="left_shoulder_roll_link_collision" material="shoulder_roll_link_visual_material"/>
        <body name="left_shoulder_gear_drive" pos="0.019 0.024 -0.019" quat="1 0 0 0">
          <joint axis="0.0 0.0 1.0" name="left_shoulder_yaw_drive" type="hinge" range="-3.141592653589776 3.1415926535898104" class="2XC430"/>
          <inertial pos="2.34689e-15 1.16905e-15 -0.00662386" mass="0.004" fullinertia="1.9527e-07 1.9527e-07 2.87762e-07 -2.80555e-15 -1.24615e-36 -9.18142e-36"/>
          <geom type="mesh" class="visual" pos="2.34689e-15 1.17341e-15 -0.00662386" quat="1.0 1.70872e-13 3.26351e-13 4.28798e-14" mesh="left_shoulder_gear_drive_visual" material="shoulder_gear_drive_visual_material"/>
        </body>
        <body name="left_shoulder_yaw_link" pos="0.019 3.58104e-10 -0.025" quat="1 0 0 0">
          <joint axis="0.0 0.0 -1.0" name="left_shoulder_yaw_driven" type="hinge" range="-3.1415926535898104 3.141592653589776"/>
          <inertial pos="-5.55746e-18 1.46642e-16 -0.0257843" mass="0.0247439" fullinertia="1.01507e-05 1.54061e-05 6.98599e-06 -1.01939e-12 -1.24915e-20 -9.15788e-20"/>
          <geom type="mesh" class="visual" pos="-5.4121100000000004e-18 1.4858e-16 -0.0257843" quat="1.0 -9.49518e-14 2.33442e-13 8.91876e-15" mesh="left_shoulder_yaw_link_visual" material="shoulder_yaw_link_visual_material"/>
          <geom type="box" class="collision" pos="-1.47382e-17 4.9127400000000006e-18 -0.04425" quat="1.0 -9.49518e-14 2.33442e-13 8.91876e-15" size="0.023 0.0129925 0.027107" name="left_shoulder_yaw_link_collision" material="shoulder_yaw_link_visual_material"/>
          <body name="left_elbow_roll_link" pos="-0.019 -6.66967e-17 -0.061" quat="1 0 0 0">
            <joint axis="1.0 0.0 0.0" name="left_elbow_roll" type="hinge" range="-2.268928027592625 1.9198621771937663" class="2XC430"/>
            <inertial pos="0.0185402 0.0117736 -0.00203648" mass="0.1152" fullinertia="2.66052e-05 3.22099e-05 3.47029e-05 -5.25219e-07 -3.29206e-08 6.36632e-07"/>
            <geom type="mesh" class="visual" pos="0.0185402 0.0117736 -0.00203648" quat="-1.0 -2.77556e-17 -1.94289e-16 1.94289e-16" mesh="left_elbow_roll_link_visual" material="elbow_roll_link_visual_material"/>
            <geom type="box" class="collision" pos="0.01855 0.012 -0.003" quat="-1.0 -2.77556e-17 -1.94289e-16 1.94289e-16" size="0.02045 0.02325 0.023" name="left_elbow_roll_link_collision" material="elbow_roll_link_visual_material"/>
            <body name="left_elbow_gear_drive" pos="0.019 0.024 -0.019" quat="1 0 0 0">
              <joint axis="0.0 0.0 1.0" name="left_elbow_yaw_drive" type="hinge" range="-3.141592653589993 3.1415926535895933" class="2XC430"/>
              <inertial pos="-2.35162e-15 -1.16306e-15 -0.00662386" mass="0.004" fullinertia="1.9527e-07 1.9527e-07 2.87762e-07 -2.80555e-15 -1.20371e-35 6.01853e-36"/>
              <geom type="mesh" class="visual" pos="-2.35162e-15 -1.16573e-15 -0.00662386" quat="-1.0 7.83817e-14 -2.51986e-13 -4.16613e-14" mesh="left_elbow_gear_drive_visual" material="elbow_gear_drive_visual_material"/>
            </body>
            <body name="left_elbow_yaw_link" pos="0.019 3.58086e-10 -0.025" quat="1 0 0 0">
              <joint axis="0.0 0.0 -1.0" name="left_elbow_yaw_driven" type="hinge" range="-3.1415926535895933 3.141592653589993"/>
              <inertial pos="2.3429e-12 0.00604452 -0.0333598" mass="0.0295299" fullinertia="2.81941e-05 1.64675e-05 1.38153e-05 2.82975e-13 -5.9306e-15 3.43094e-06"/>
              <geom type="mesh" class="visual" pos="2.3429e-12 0.00604452 -0.0333598" quat="1.0 -2.40411e-13 7.58629e-14 -9.1531e-14" mesh="left_elbow_yaw_link_visual" material="elbow_yaw_link_visual_material"/>
              <geom type="box" class="collision" pos="-1.85713e-17 0.00335 -0.04475" quat="1.0 -2.40411e-13 7.58629e-14 -9.1531e-14" size="0.0129925 0.02965 0.027563" name="left_elbow_yaw_link_collision" material="elbow_yaw_link_visual_material"/>
              <body name="left_wrist_pitch_link" pos="2.52308e-17 0.022 -0.061" quat="1 0 0 0">
                <joint axis="0.0 -1.0 0.0" name="left_wrist_pitch_driven" type="hinge" range="-2.0943951023930456 2.094395102393345"/>
                <inertial pos="-0.000415054 -0.021867 0.0114965" mass="0.1276" fullinertia="3.29851e-05 4.15884e-05 3.57365e-05 1.8622e-08 -1.99325e-07 5.35804e-07"/>
                <geom type="mesh" class="visual" pos="-0.000415054 -0.021867 0.0114965" quat="-1.0 0.0 -2.22045e-16 2.22045e-16" mesh="left_wrist_pitch_link_visual" material="wrist_pitch_link_visual_material"/>
                <geom type="box" class="collision" pos="-0.00045 -0.0215 0.012" quat="-1.0 0.0 -2.22045e-16 2.22045e-16" size="0.02045 0.0225 0.02325" name="left_wrist_pitch_link_collision" material="wrist_pitch_link_visual_material"/>
                <body name="left_wrist_gear_drive" pos="1.52465e-10 -0.003 0.024" quat="1 0 0 0">
                  <joint axis="0.0 1.0 0.0" name="left_wrist_pitch_drive" type="hinge" range="-2.094395102393345 2.0943951023930456" class="2XC430"/>
                  <inertial pos="-2.9081e-16 0.00503438 -4.09694e-15" mass="0.003" fullinertia="1.33264e-07 1.33264e-07 2.24433e-07 1.59295e-15 2.06143e-35 2.81059e-36"/>
                  <geom type="mesh" class="visual" pos="-2.9081e-16 0.00503438 -4.09451e-15" quat="-1.0 3.95683e-13 -2.88508e-13 9.20696e-14" mesh="left_wrist_gear_drive_visual" material="wrist_gear_drive_visual_material"/>
                </body>
                <body name="left_gripper_link" pos="-0.019 -0.022 -3.58073e-10" quat="1 0 0 0">
                  <joint axis="-1.0 0.0 0.0" name="left_wrist_roll" type="hinge" range="-1.5707963267948966 1.5707963267948966" class="2XC430"/>
                  <inertial pos="0.00528675 0.00369019 -0.0303168" mass="0.0687174" fullinertia="5.33011e-05 5.37576e-05 1.75922e-05 1.3631e-06 4.88064e-06 -6.91681e-06"/>
                  <geom type="mesh" class="visual" pos="0.00528675 0.00369019 -0.0303168" quat="-1.0 0.0 -2.22045e-16 2.22045e-16" mesh="left_gripper_link_visual" material="gripper_link_visual_material"/>
                  <geom type="box" class="collision" pos="0.019 0.002925 -0.02885" quat="-1.0 0.0 -2.22045e-16 2.22045e-16" size="0.045 0.024675 0.01815" name="left_gripper_link_collision" material="gripper_link_visual_material"/>
                  <body name="left_gripper_gear_drive" pos="-0.01195 0.0001 -0.0397" quat="1 0 0 0">
                    <joint axis="0.0 0.0 1.0" name="left_gripper_rack" type="hinge" range="0.0 1.9547687622336491" class="XC330"/>
                    <inertial pos="3.35843e-17 -2.99512e-17 -0.0025" mass="0.00107037" fullinertia="2.73249e-08 2.73249e-08 5.01899e-08 -4.15441e-38 -3.76985e-41 5.10422e-39"/>
                    <geom type="mesh" class="visual" pos="3.35843e-17 -2.77556e-17 -0.0025" quat="-1.0 4.44089e-16 2.97979e-16 3.11762e-14" mesh="left_gripper_gear_drive_visual" material="gripper_gear_drive_visual_material"/>
                  </body>
                  <body name="left_gripper_finger" pos="-0.026 -0.015975 -0.03985" quat="1 0 0 0">
                    <joint axis="1.0 0.0 0.0" name="left_gripper_pinion" type="slide" range="-0.0008730000000025674 0.023499999999997433"/>
                    <inertial pos="0.00981816 0.0160522 -0.0386855" mass="0.0265733" fullinertia="1.03138e-05 5.64357e-06 1.268e-05 8.26278e-08 6.65994e-08 2.09843e-08"/>
                    <geom type="mesh" class="visual" pos="0.00981816 0.0160522 -0.0386855" quat="-1.0 -8.32667e-17 -5.27356e-16 3.60822e-16" mesh="left_gripper_finger_visual" material="gripper_finger_visual_material"/>
                    <geom type="box" class="collision" pos="0.0045 0.016125 -0.027" quat="-1.0 -8.32667e-17 -5.27356e-16 3.60822e-16" size="0.0045 0.02035 0.019" name="left_gripper_finger_collision_0" material="gripper_finger_visual_material"/>
                    <geom type="box" class="collision" pos="0.01075 0.016125 -0.055" quat="-1.0 -8.32667e-17 -5.27356e-16 3.60822e-16" size="0.01075 0.02035 0.009" name="left_gripper_finger_collision_1" material="gripper_finger_visual_material"/>
                    <site name="left_hand_center" pos="0.045 0.016125 -0.027" type="sphere" size="0.005" rgba="0.9 0.1 0.1 0.8"/>
                  </body>
                  <body name="left_gripper_finger_2" pos="0.064 0.015975 -0.03985" quat="1 0 0 0">
                    <joint axis="-1.0 0.0 0.0" name="left_gripper_pinion_mirror" type="slide" range="-0.0008729999999974465 0.023500000000002554"/>
                    <inertial pos="-0.00981816 -0.0160522 -0.0386855" mass="0.0265733" fullinertia="1.03138e-05 5.64357e-06 1.268e-05 8.26278e-08 6.65994e-08 2.09843e-08"/>
                    <geom type="mesh" class="visual" pos="-0.00981816 -0.0160522 -0.0386855" quat="-1.0 2.77556e-17 -4.16334e-16 2.498e-16" mesh="left_gripper_finger_2_visual" material="gripper_finger_2_visual_material"/>
                    <geom type="box" class="collision" pos="-0.0045 -0.016125 -0.027" quat="-1.0 2.77556e-17 -4.16334e-16 2.498e-16" size="0.0045 0.02035 0.019" name="left_gripper_finger_2_collision_0" material="gripper_finger_2_visual_material"/>
                    <geom type="box" class="collision" pos="-0.01075 -0.016125 -0.055" quat="-1.0 2.77556e-17 -4.16334e-16 2.498e-16" size="0.01075 0.02035 0.009" name="left_gripper_finger_2_collision_1" material="gripper_finger_2_visual_material"/>
                  </body>
                </body>
              </body>
            </body>
          </body>
        </body>
      </body>
    </body>
    <body name="right_shoulder_pitch_link" pos="-0.0200079 -0.067 0.10175" quat="1 0 0 0">
      <joint axis="0.0 -1.0 0.0" name="right_shoulder_pitch" type="hinge" range="-3.14159265358977 3.141592653589816" class="XC430"/>
      <inertial pos="3.0674600000000003e-18 -0.0129132 1.4033500000000001e-18" mass="0.015" fullinertia="3.20331e-06 6.13264e-06 6.99606e-06 1.70329e-30 -6.77993e-21 5.76128e-19"/>
      <geom type="mesh" class="visual" pos="3.0674600000000003e-18 -0.0129132 1.4033500000000001e-18" quat="1.0 1.6549200000000004e-32 1.2727900000000001e-18 1.2727900000000001e-18" mesh="right_shoulder_pitch_link_visual" material="shoulder_pitch_link_visual_material"/>
      <body name="right_shoulder_roll_link" pos="0.019 -0.027 -1.42914e-16" quat="1 0 0 0">
        <joint axis="-1.0 0.0 0.0" name="right_shoulder_roll" type="hinge" range="-0.4363323129980788 1.5707963267954002" class="2XC430"/>
        <inertial pos="-0.0185402 -0.0117736 -0.00203648" mass="0.1152" fullinertia="2.66052e-05 3.22099e-05 3.47029e-05 -5.25219e-07 3.29206e-08 -6.36632e-07"/>
        <geom type="mesh" class="visual" pos="-0.0185402 -0.0117736 -0.00203648" quat="1.0 0.0 0.0 0.0" mesh="right_shoulder_roll_link_visual" material="shoulder_roll_link_visual_material"/>
        <geom type="box" class="collision" pos="-0.01855 -0.012 -0.003" quat="1.0 0.0 0.0 0.0" size="0.02045 0.02325 0.023" name="right_shoulder_roll_link_collision" material="shoulder_roll_link_visual_material"/>
        <body name="right_shoulder_gear_drive" pos="-0.019 -0.024 -0.019" quat="1 0 0 0">
          <joint axis="0.0 0.0 1.0" name="right_shoulder_yaw_drive" type="hinge" range="-3.141592653589815 3.1415926535897714" class="2XC430"/>
          <inertial pos="-2.34906e-15 -1.16262e-15 -0.00662386" mass="0.004" fullinertia="1.9527e-07 1.9527e-07 2.87762e-07 -2.80555e-15 2.41503e-36 9.42346e-36"/>
          <geom type="mesh" class="visual" pos="-2.34906e-15 -1.16573e-15 -0.00662386" quat="1.0 -1.5965e-13 -3.28014e-13 4.41543e-14" mesh="right_shoulder_gear_drive_visual" material="shoulder_gear_drive_visual_material"/>
        </body>
        <body name="right_shoulder_yaw_link" pos="-0.019 -3.58104e-10 -0.025" quat="1 0 0 0">
          <joint axis="0.0 0.0 -1.0" name="right_shoulder_yaw_driven" type="hinge" range="-3.1415926535897714 3.141592653589815"/>
          <inertial pos="-3.5508000000000004e-18 -1.41456e-16 -0.0257843" mass="0.0247439" fullinertia="1.01507e-05 1.54061e-05 6.98599e-06 -1.01939e-12 -4.89016e-22 -7.44876e-20"/>
          <geom type="mesh" class="visual" pos="-3.7357400000000006e-18 -1.38778e-16 -0.0257843" quat="1.0 9.75616e-14 -2.38868e-13 -1.09448e-14" mesh="right_shoulder_yaw_link_visual" material="shoulder_yaw_link_visual_material"/>
          <geom type="box" class="collision" pos="0.0 0.0 -0.04425" quat="1.0 9.75616e-14 -2.38868e-13 -1.09448e-14" size="0.023 0.0129925 0.027107" name="right_shoulder_yaw_link_collision" material="shoulder_yaw_link_visual_material"/>
          <body name="right_elbow_roll_link" pos="0.019 -6.245e-17 -0.061" quat="1 0 0 0">
            <joint axis="-1.0 0.0 0.0" name="right_elbow_roll" type="hinge" range="-2.268928027592629 1.919862177193762" class="2XC430"/>
            <inertial pos="-0.0185402 -0.0117736 -0.00203648" mass="0.1152" fullinertia="2.66052e-05 3.22099e-05 3.47029e-05 -5.25219e-07 -3.29206e-08 6.36632e-07"/>
            <geom type="mesh" class="visual" pos="-0.0185402 -0.0117736 -0.00203648" quat="1.0 0.0 0.0 0.0" mesh="right_elbow_roll_link_visual" material="elbow_roll_link_visual_material"/>
            <geom type="box" class="collision" pos="-0.01855 -0.012 -0.003" quat="1.0 0.0 0.0 0.0" size="0.02045 0.02325 0.023" name="right_elbow_roll_link_collision" material="elbow_roll_link_visual_material"/>
            <body name="right_elbow_gear_drive" pos="-0.019 -0.024 -0.019" quat="1 0 0 0">
              <joint axis="0.0 0.0 1.0" name="right_elbow_yaw_drive" type="hinge" range="-3.1415926535899983 3.141592653589588" class="2XC430"/>
              <inertial pos="2.34906e-15 1.16429e-15 -0.00662386" mass="0.004" fullinertia="1.9527e-07 1.9527e-07 2.87762e-07 -2.80555e-15 -5.20428e-35 1.03563e-36"/>
              <geom type="mesh" class="visual" pos="2.34906e-15 1.16573e-15 -0.00662386" quat="1.0 9.54634e-14 -2.58793e-13 2.3612e-14" mesh="right_elbow_gear_drive_visual" material="elbow_gear_drive_visual_material"/>
            </body>
            <body name="right_elbow_yaw_link" pos="-0.019 -3.58087e-10 -0.025" quat="1 0 0 0">
              <joint axis="0.0 0.0 -1.0" name="right_elbow_yaw_driven" type="hinge" range="-3.141592653589588 3.1415926535899983"/>
              <inertial pos="-2.3429e-12 -0.00604452 -0.0333598" mass="0.0295299" fullinertia="2.81941e-05 1.64675e-05 1.38153e-05 2.82975e-13 -5.93063e-15 3.43094e-06"/>
              <geom type="mesh" class="visual" pos="-2.3429e-12 -0.00604452 -0.0333598" quat="1.0 2.47969e-13 -7.71174e-14 -1.12715e-13" mesh="right_elbow_yaw_link_visual" material="elbow_yaw_link_visual_material"/>
              <geom type="box" class="collision" pos="0.0 -0.00335 -0.04475" quat="1.0 2.47969e-13 -7.71174e-14 -1.12715e-13" size="0.0129925 0.02965 0.027563" name="right_elbow_yaw_link_collision" material="elbow_yaw_link_visual_material"/>
              <body name="right_wrist_pitch_link" pos="1.47538e-15 -0.022 -0.061" quat="1 0 0 0">
                <joint axis="0.0 1.0 0.0" name="right_wrist_pitch_driven" type="hinge" range="-2.0943951023930585 2.094395102393332"/>
                <inertial pos="0.000415054 0.021867 0.0114965" mass="0.1276" fullinertia="3.29851e-05 4.15884e-05 3.57365e-05 1.8622e-08 -1.99325e-07 5.35804e-07"/>
                <geom type="mesh" class="visual" pos="0.000415054 0.021867 0.0114965" quat="-1.0 0.0 0.0 0.0" mesh="right_wrist_pitch_link_visual" material="wrist_pitch_link_visual_material"/>
                <geom type="box" class="collision" pos="0.00045 0.0215 0.012" quat="-1.0 0.0 0.0 0.0" size="0.02045 0.0225 0.02325" name="right_wrist_pitch_link_collision" material="wrist_pitch_link_visual_material"/>
                <body name="right_wrist_gear_drive" pos="-1.52465e-10 0.003 0.024" quat="1 0 0 0">
                  <joint axis="0.0 -1.0 0.0" name="right_wrist_pitch_drive" type="hinge" range="-2.094395102393332 2.0943951023930585" class="2XC430"/>
                  <inertial pos="2.90543e-16 -0.00503438 -3.98028e-15" mass="0.003" fullinertia="1.33264e-07 1.33264e-07 2.24433e-07 1.59295e-15 -4.95221e-36 8.01531e-36"/>
                  <geom type="mesh" class="visual" pos="2.90543e-16 -0.00503438 -3.97788e-15" quat="1.0 3.86857e-13 -2.88733e-13 -1.12818e-13" mesh="right_wrist_gear_drive_visual" material="wrist_gear_drive_visual_material"/>
                </body>
                <body name="right_gripper_link" pos="0.019 0.022 -3.58073e-10" quat="1 0 0 0">
                  <joint axis="1.0 0.0 0.0" name="right_wrist_roll" type="hinge" range="-1.5707963267948966 1.5707963267948966" class="2XC430"/>
                  <inertial pos="-0.0327167 -0.0037537 -0.0303168" mass="0.0687174" fullinertia="5.33094e-05 5.37334e-05 1.75597e-05 1.34048e-06 4.88118e-06 -6.91683e-06"/>
                  <geom type="mesh" class="visual" pos="-0.0327167 -0.0037537 -0.0303168" quat="-1.0 0.0 0.0 0.0" mesh="right_gripper_link_visual" material="gripper_link_visual_material"/>
                  <geom type="box" class="collision" pos="-0.019 -0.002925 -0.02885" quat="-1.0 0.0 0.0 0.0" size="0.045 0.024675 0.01815" name="right_gripper_link_collision" material="gripper_link_visual_material"/>
                  <body name="right_gripper_gear_drive" pos="-0.04995 -0.0001 -0.0397" quat="1 0 0 0">
                    <joint axis="0.0 0.0 1.0" name="right_gripper_rack" type="hinge" range="0.0 1.9547687622336491" class="XC330"/>
                    <inertial pos="-3.1225e-17 3.21537e-17 -0.0025" mass="0.00107037" fullinertia="2.73249e-08 2.73249e-08 5.01899e-08 2.0899e-37 -4.56577e-40 1.65269e-40"/>
                    <geom type="mesh" class="visual" pos="-3.1225e-17 3.1225e-17 -0.0025" quat="-1.0 0.0 0.0 1.06767e-13" mesh="right_gripper_gear_drive_visual" material="gripper_gear_drive_visual_material"/>
                  </body>
                  <body name="right_gripper_finger" pos="-0.064 -0.015975 -0.03985" quat="1 0 0 0">
                    <joint axis="1.0 0.0 0.0" name="right_gripper_pinion" type="slide" range="-0.000872999999993866 0.023500000000006134"/>
                    <inertial pos="0.00981816 0.0160522 -0.0386855" mass="0.0265733" fullinertia="1.03138e-05 5.64357e-06 1.268e-05 8.26278e-08 6.65994e-08 2.09843e-08"/>
                    <geom type="mesh" class="visual" pos="0.00981816 0.0160522 -0.0386855" quat="-1.0 3.05311e-16 1.36002e-15 -7.49401e-16" mesh="right_gripper_finger_visual" material="gripper_finger_visual_material"/>
                    <geom type="box" class="collision" pos="0.0045 0.016125 -0.027" quat="-1.0 3.05311e-16 1.36002e-15 -7.49401e-16" size="0.0045 0.02035 0.019" name="right_gripper_finger_collision_0" material="gripper_finger_visual_material"/>
                    <geom type="box" class="collision" pos="0.01075 0.016125 -0.055" quat="-1.0 3.05311e-16 1.36002e-15 -7.49401e-16" size="0.01075 0.02035 0.009" name="right_gripper_finger_collision_1" material="gripper_finger_visual_material"/>
                    <site name="right_hand_center" pos="0.045 0.016125 -0.027" type="sphere" size="0.005" rgba="0.9 0.1 0.1 0.8"/>
                  </body>
                  <body name="right_gripper_finger_2" pos="0.026 0.015975 -0.03985" quat="1 0 0 0">
                    <joint axis="-1.0 0.0 0.0" name="right_gripper_pinion_mirror" type="slide" range="-0.000873000000007036 0.023499999999992964"/>
                    <inertial pos="-0.00981816 -0.0160522 -0.0386855" mass="0.0265733" fullinertia="1.03138e-05 5.64357e-06 1.268e-05 8.26278e-08 6.65994e-08 2.09843e-08"/>
                    <geom type="mesh" class="visual" pos="-0.00981816 -0.0160522 -0.0386855" quat="1.0 2.77556e-17 -2.77556e-17 -1.38778e-16" mesh="right_gripper_finger_2_visual" material="gripper_finger_2_visual_material"/>
                    <geom type="box" class="collision" pos="-0.0045 -0.016125 -0.027" quat="1.0 2.77556e-17 -2.77556e-17 -1.38778e-16" size="0.0045 0.02035 0.019" name="right_gripper_finger_2_collision_0" material="gripper_finger_2_visual_material"/>
                    <geom type="box" class="collision" pos="-0.01075 -0.016125 -0.055" quat="1.0 2.77556e-17 -2.77556e-17 -1.38778e-16" size="0.01075 0.02035 0.009" name="right_gripper_finger_2_collision_1" material="gripper_finger_2_visual_material"/>
                  </body>
                </body>
              </body>
            </body>
          </body>
        </body>
      </body>
    </body>
  </worldbody>
  <asset>
    <mesh file="head_visual.stl"/>
    <mesh file="left_ankle_pitch_link_visual.stl"/>
    <mesh file="left_ankle_roll_link_collision.stl"/>
    <mesh file="left_ankle_roll_link_visual.stl"/>
    <mesh file="left_elbow_gear_drive_visual.stl"/>
    <mesh file="left_elbow_roll_link_visual.stl"/>
    <mesh file="left_elbow_yaw_link_visual.stl"/>
    <mesh file="left_gripper_finger_2_visual.stl"/>
    <mesh file="left_gripper_finger_visual.stl"/>
    <mesh file="left_gripper_gear_drive_visual.stl"/>
    <mesh file="left_gripper_link_visual.stl"/>
    <mesh file="left_hip_pitch_link_visual.stl"/>
    <mesh file="left_hip_roll_link_visual.stl"/>
    <mesh file="left_hip_yaw_gear_drive_visual.stl"/>
    <mesh file="left_hip_yaw_link_visual.stl"/>
    <mesh file="left_knee_link_visual.stl"/>
    <mesh file="left_shoulder_gear_drive_visual.stl"/>
    <mesh file="left_shoulder_pitch_link_visual.stl"/>
    <mesh file="left_shoulder_roll_link_visual.stl"/>
    <mesh file="left_shoulder_yaw_link_visual.stl"/>
    <mesh file="left_wrist_gear_drive_visual.stl"/>
    <mesh file="left_wrist_pitch_link_visual.stl"/>
    <mesh file="neck_pitch_plate_visual.stl"/>
    <mesh file="neck_rod_2_visual.stl"/>
    <mesh file="neck_rod_visual.stl"/>
    <mesh file="neck_yaw_gear_drive_visual.stl"/>
    <mesh file="neck_yaw_link_visual.stl"/>
    <mesh file="pelvis_link_visual.stl"/>
    <mesh file="right_ankle_pitch_link_visual.stl"/>
    <mesh file="right_ankle_roll_link_collision.stl"/>
    <mesh file="right_ankle_roll_link_visual.stl"/>
    <mesh file="right_elbow_gear_drive_visual.stl"/>
    <mesh file="right_elbow_roll_link_visual.stl"/>
    <mesh file="right_elbow_yaw_link_visual.stl"/>
    <mesh file="right_gripper_finger_2_visual.stl"/>
    <mesh file="right_gripper_finger_visual.stl"/>
    <mesh file="right_gripper_gear_drive_visual.stl"/>
    <mesh file="right_gripper_link_visual.stl"/>
    <mesh file="right_hip_pitch_link_visual.stl"/>
    <mesh file="right_hip_roll_link_visual.stl"/>
    <mesh file="right_hip_yaw_gear_drive_visual.stl"/>
    <mesh file="right_hip_yaw_link_visual.stl"/>
    <mesh file="right_knee_link_visual.stl"/>
    <mesh file="right_shoulder_gear_drive_visual.stl"/>
    <mesh file="right_shoulder_pitch_link_visual.stl"/>
    <mesh file="right_shoulder_roll_link_visual.stl"/>
    <mesh file="right_shoulder_yaw_link_visual.stl"/>
    <mesh file="right_wrist_gear_drive_visual.stl"/>
    <mesh file="right_wrist_pitch_link_visual.stl"/>
    <mesh file="torso_visual.stl"/>
    <mesh file="waist_gear_drive_2_visual.stl"/>
    <mesh file="waist_gear_drive_visual.stl"/>
    <mesh file="waist_gears_visual.stl"/>
    <material name="ankle_pitch_link_visual_material" rgba="0.708413 0.627926 0.367392 1"/>
    <material name="ankle_roll_link_visual_material" rgba="0.615686 0.811765 0.929412 1"/>
    <material name="elbow_gear_drive_visual_material" rgba="0.615686 0.811765 0.929412 1"/>
    <material name="elbow_roll_link_visual_material" rgba="0.75922 0.862174 0.917756 1"/>
    <material name="elbow_yaw_link_visual_material" rgba="0.516885 0.653641 0.793594 1"/>
    <material name="gripper_finger_2_visual_material" rgba="0.615686 0.811765 0.929412 1"/>
    <material name="gripper_finger_visual_material" rgba="0.615686 0.811765 0.929412 1"/>
    <material name="gripper_gear_drive_visual_material" rgba="0.647059 0.647059 0.647059 1"/>
    <material name="gripper_link_visual_material" rgba="0.630539 0.762991 0.810843 1"/>
    <material name="head_visual_material" rgba="0.628184 0.794414 0.875689 1"/>
    <material name="hip_pitch_link_visual_material" rgba="0.940459 0.715563 0.0942225 1"/>
    <material name="hip_roll_link_visual_material" rgba="0.615686 0.811765 0.929412 1"/>
    <material name="hip_yaw_gear_drive_visual_material" rgba="0.615686 0.811765 0.929412 1"/>
    <material name="hip_yaw_link_visual_material" rgba="0.801331 0.729185 0.393273 1"/>
    <material name="knee_link_visual_material" rgba="0.615686 0.811765 0.929412 1"/>
    <material name="neck_pitch_plate_visual_material" rgba="0.647059 0.647059 0.647059 1"/>
    <material name="neck_rod_2_visual_material" rgba="0.62596 0.757827 0.836947 1"/>
    <material name="neck_rod_visual_material" rgba="0.62596 0.757827 0.836947 1"/>
    <material name="neck_yaw_gear_drive_visual_material" rgba="0.647059 0.647059 0.647059 1"/>
    <material name="neck_yaw_link_visual_material" rgba="0.231373 0.380392 0.705882 1"/>
    <material name="pelvis_link_visual_material" rgba="0.642812 0.76997 0.800997 1"/>
    <material name="shoulder_gear_drive_visual_material" rgba="0.615686 0.811765 0.929412 1"/>
    <material name="shoulder_pitch_link_visual_material" rgba="0.615686 0.811765 0.929412 1"/>
    <material name="shoulder_roll_link_visual_material" rgba="0.75922 0.862174 0.917756 1"/>
    <material name="shoulder_yaw_link_visual_material" rgba="0.542005 0.729062 0.886557 1"/>
    <material name="torso_visual_material" rgba="0.63539 0.796011 0.905481 1"/>
    <material name="waist_gear_drive_2_visual_material" rgba="0.647059 0.647059 0.647059 1"/>
    <material name="waist_gear_drive_visual_material" rgba="0.647059 0.647059 0.647059 1"/>
    <material name="waist_gears_visual_material" rgba="0.307262 0.428048 0.687761 1"/>
    <material name="wrist_gear_drive_visual_material" rgba="0.615686 0.811765 0.929412 1"/>
    <material name="wrist_pitch_link_visual_material" rgba="0.748702 0.84202 0.892409 1"/>
  </asset>
  <actuator>
    <motor name="neck_yaw_drive" joint="neck_yaw_drive"/>
    <motor name="neck_pitch_act" joint="neck_pitch_act"/>
    <motor name="waist_act_1" joint="waist_act_1"/>
    <motor name="waist_act_2" joint="waist_act_2"/>
    <motor name="left_hip_pitch" joint="left_hip_pitch"/>
    <motor name="left_hip_roll" joint="left_hip_roll"/>
    <motor name="left_hip_yaw_drive" joint="left_hip_yaw_drive"/>
    <motor name="left_knee" joint="left_knee"/>
    <motor name="left_ankle_roll" joint="left_ankle_roll"/>
    <motor name="left_ankle_pitch" joint="left_ankle_pitch"/>
    <motor name="right_hip_pitch" joint="right_hip_pitch"/>
    <motor name="right_hip_roll" joint="right_hip_roll"/>
    <motor name="right_hip_yaw_drive" joint="right_hip_yaw_drive"/>
    <motor name="right_knee" joint="right_knee"/>
    <motor name="right_ankle_roll" joint="right_ankle_roll"/>
    <motor name="right_ankle_pitch" joint="right_ankle_pitch"/>
    <motor name="left_shoulder_pitch" joint="left_shoulder_pitch"/>
    <motor name="left_shoulder_roll" joint="left_shoulder_roll"/>
    <motor name="left_shoulder_yaw_drive" joint="left_shoulder_yaw_drive"/>
    <motor name="left_elbow_roll" joint="left_elbow_roll"/>
    <motor name="left_elbow_yaw_drive" joint="left_elbow_yaw_drive"/>
    <motor name="left_wrist_pitch_drive" joint="left_wrist_pitch_drive"/>
    <motor name="left_wrist_roll" joint="left_wrist_roll"/>
    <motor name="right_shoulder_pitch" joint="right_shoulder_pitch"/>
    <motor name="right_shoulder_roll" joint="right_shoulder_roll"/>
    <motor name="right_shoulder_yaw_drive" joint="right_shoulder_yaw_drive"/>
    <motor name="right_elbow_roll" joint="right_elbow_roll"/>
    <motor name="right_elbow_yaw_drive" joint="right_elbow_yaw_drive"/>
    <motor name="right_wrist_pitch_drive" joint="right_wrist_pitch_drive"/>
    <motor name="right_wrist_roll" joint="right_wrist_roll"/>
    <motor name="left_gripper_rack" joint="left_gripper_rack"/>
    <motor name="right_gripper_rack" joint="right_gripper_rack"/>
  </actuator>
  <equality>
    <connect site1="closing_neck_pitch_front_1" site2="closing_neck_pitch_front_2" solref="0.004 1" solimp="0.9999 0.9999 0.001 0.5 2"/>
    <connect site1="closing_neck_pitch_front_1_z" site2="closing_neck_pitch_front_2_z" solref="0.004 1" solimp="0.9999 0.9999 0.001 0.5 2"/>
    <connect site1="closing_neck_pitch_back_1" site2="closing_neck_pitch_back_2" solref="0.004 1" solimp="0.9999 0.9999 0.001 0.5 2"/>
    <connect site1="closing_neck_pitch_back_1_z" site2="closing_neck_pitch_back_2_z" solref="0.004 1" solimp="0.9999 0.9999 0.001 0.5 2"/>
    <joint joint1="neck_yaw_driven" joint2="neck_yaw_drive" polycoef="0 -0.9090909091 0 0 0"/>
    <joint joint1="left_shoulder_yaw_driven" joint2="left_shoulder_yaw_drive" polycoef="0 -1.0 0 0 0"/>
    <joint joint1="left_elbow_yaw_driven" joint2="left_elbow_yaw_drive" polycoef="0 -1.0 0 0 0"/>
    <joint joint1="left_wrist_pitch_driven" joint2="left_wrist_pitch_drive" polycoef="0 -1.0 0 0 0"/>
    <joint joint1="left_hip_yaw_driven" joint2="left_hip_yaw_drive" polycoef="0 -0.8571428571 0 0 0"/>
    <joint joint1="right_shoulder_yaw_driven" joint2="right_shoulder_yaw_drive" polycoef="0 -1.0 0 0 0"/>
    <joint joint1="right_elbow_yaw_driven" joint2="right_elbow_yaw_drive" polycoef="0 -1.0 0 0 0"/>
    <joint joint1="right_wrist_pitch_driven" joint2="right_wrist_pitch_drive" polycoef="0 -1.0 0 0 0"/>
    <joint joint1="right_hip_yaw_driven" joint2="right_hip_yaw_drive" polycoef="0 -0.8571428571 0 0 0"/>
    <joint joint1="left_gripper_pinion" joint2="left_gripper_rack" polycoef="0 0.012 0 0 0" solimp="0.9999 0.9999 0.001 0.5 2" solref="0.004 1"/>
    <joint joint1="left_gripper_pinion_mirror" joint2="left_gripper_rack" polycoef="0 0.012 0 0 0" solimp="0.9999 0.9999 0.001 0.5 2" solref="0.004 1"/>
    <joint joint1="right_gripper_pinion" joint2="right_gripper_rack" polycoef="0 0.012 0 0 0" solimp="0.9999 0.9999 0.001 0.5 2" solref="0.004 1"/>
    <joint joint1="right_gripper_pinion_mirror" joint2="right_gripper_rack" polycoef="0 0.012 0 0 0" solimp="0.9999 0.9999 0.001 0.5 2" solref="0.004 1"/>
  </equality>
  <tendon>
    <fixed name="waist_roll_coupling" limited="true" range="-0.03 0.03">
      <joint joint="waist_act_1" coef="0.29166667"/>
      <joint joint="waist_act_2" coef="-0.29166667"/>
      <joint joint="waist_roll" coef="1"/>
    </fixed>
    <fixed name="waist_yaw_coupling" limited="true" range="-0.001 0.001">
      <joint joint="waist_act_1" coef="-0.20833333"/>
      <joint joint="waist_act_2" coef="-0.20833333"/>
      <joint joint="waist_yaw" coef="1"/>
    </fixed>
  </tendon>
  <contact>
    <pair geom1="torso_collision_0" geom2="left_shoulder_yaw_link_collision"/>
    <pair geom1="torso_collision_0" geom2="left_elbow_roll_link_collision"/>
    <pair geom1="torso_collision_0" geom2="left_elbow_yaw_link_collision"/>
    <pair geom1="torso_collision_0" geom2="left_wrist_pitch_link_collision"/>
    <pair geom1="torso_collision_0" geom2="right_shoulder_yaw_link_collision"/>
    <pair geom1="torso_collision_0" geom2="right_elbow_roll_link_collision"/>
    <pair geom1="torso_collision_0" geom2="right_elbow_yaw_link_collision"/>
    <pair geom1="torso_collision_0" geom2="right_wrist_pitch_link_collision"/>
    <pair geom1="torso_collision_1" geom2="left_elbow_yaw_link_collision"/>
    <pair geom1="torso_collision_1" geom2="left_wrist_pitch_link_collision"/>
    <pair geom1="torso_collision_1" geom2="right_elbow_yaw_link_collision"/>
    <pair geom1="torso_collision_1" geom2="right_wrist_pitch_link_collision"/>
    <pair geom1="head_collision" geom2="left_shoulder_yaw_link_collision"/>
    <pair geom1="head_collision" geom2="left_elbow_roll_link_collision"/>
    <pair geom1="head_collision" geom2="left_elbow_yaw_link_collision"/>
    <pair geom1="head_collision" geom2="left_wrist_pitch_link_collision"/>
    <pair geom1="head_collision" geom2="right_shoulder_yaw_link_collision"/>
    <pair geom1="head_collision" geom2="right_elbow_roll_link_collision"/>
    <pair geom1="head_collision" geom2="right_elbow_yaw_link_collision"/>
    <pair geom1="head_collision" geom2="right_wrist_pitch_link_collision"/>
    <pair geom1="pelvis_link_collision" geom2="left_elbow_yaw_link_collision"/>
    <pair geom1="pelvis_link_collision" geom2="left_wrist_pitch_link_collision"/>
    <pair geom1="pelvis_link_collision" geom2="right_elbow_yaw_link_collision"/>
    <pair geom1="pelvis_link_collision" geom2="right_wrist_pitch_link_collision"/>
    <pair geom1="left_hip_pitch_link_collision" geom2="left_ankle_pitch_link_collision"/>
    <pair geom1="left_hip_pitch_link_collision" geom2="left_elbow_yaw_link_collision"/>
    <pair geom1="left_hip_pitch_link_collision" geom2="left_wrist_pitch_link_collision"/>
    <pair geom1="left_hip_yaw_link_collision" geom2="right_hip_yaw_link_collision"/>
    <pair geom1="left_hip_yaw_link_collision" geom2="left_elbow_yaw_link_collision"/>
    <pair geom1="left_hip_yaw_link_collision" geom2="left_wrist_pitch_link_collision"/>
    <pair geom1="left_knee_link_collision" geom2="right_knee_link_collision"/>
    <pair geom1="left_ankle_pitch_link_collision" geom2="right_ankle_pitch_link_collision"/>
    <pair geom1="left_ankle_roll_link_collision" geom2="right_ankle_roll_link_collision"/>
    <pair geom1="right_hip_pitch_link_collision" geom2="right_ankle_pitch_link_collision"/>
    <pair geom1="right_hip_pitch_link_collision" geom2="right_elbow_yaw_link_collision"/>
    <pair geom1="right_hip_pitch_link_collision" geom2="right_wrist_pitch_link_collision"/>
    <pair geom1="right_hip_yaw_link_collision" geom2="right_elbow_yaw_link_collision"/>
    <pair geom1="right_hip_yaw_link_collision" geom2="right_wrist_pitch_link_collision"/>
    <pair geom1="left_elbow_yaw_link_collision" geom2="right_elbow_yaw_link_collision"/>
    <pair geom1="left_elbow_yaw_link_collision" geom2="right_wrist_pitch_link_collision"/>
    <pair geom1="left_wrist_pitch_link_collision" geom2="right_elbow_yaw_link_collision"/>
    <pair geom1="left_wrist_pitch_link_collision" geom2="right_wrist_pitch_link_collision"/>
  </contact>
  <keyframe>
    <key name="home" qpos="0.0 0.0 0.0 0.0 0.0 0.0 0.0 0.0 0.0 0.0 -0.091312 0.0 0.0 0.0 -0.380812 -0.2895 0.0 0.091312 0.0 0.0 0.0 0.380812 0.2895 0.0 0.174533 0.087266 1.5708 -1.5708 -0.523599 -1.5708 1.5708 1.22173 -1.22173 0.0 0.0 0.0 0.0 -0.174533 0.087266 -1.5708 1.5708 -0.523599 1.5708 -1.5708 -1.22173 1.22173 0.0 0.0 0.0 0.0" ctrl="0.0 0.0 0.0 0.0 -0.091312 0.0 0.0 -0.380812 0.0 -0.2895 0.091312 0.0 0.0 0.380812 0.0 0.2895 0.174533 0.087266 1.5708 -0.523599 -1.5708 -1.22173 0.0 -0.174533 0.087266 -1.5708 -0.523599 1.5708 1.22173 0.0 0.0 0.0"/>
  </keyframe>
</mujoco>