<?xml version="1.0" ?>
<mujoco model="right_arm_leader">
  <compiler angle="radian" meshdir="assets" autolimits="true"/>
  <default>
    <default class="right_arm_leader">
      <joint frictionloss="0.1" armature="0.005"/>
      <position kp="50" dampratio="1"/>
      <default class="visual">
        <geom type="mesh" contype="0" conaffinity="0" group="2"/>
      </default>
      <default class="collision">
        <geom group="3"/>
      </default>
    </default>
  </default>
  <worldbody>
    <body name="shoulder_pitch_link" pos="0 0 0" quat="1 0 0 0" childclass="right_arm_leader">
      <freejoint name="shoulder_pitch_link_freejoint"/>
      <inertial pos="4.53819e-18 -0.0129132 7.89907e-19" mass="0.0086" fullinertia="1.83656e-06 3.51605e-06 4.01107e-06 -2.03967e-22 -2.10588e-21 3.33858e-19"/>
      <geom type="mesh" class="visual" pos="4.53819e-18 -0.0129132 7.89907e-19" quat="1 0 0 0" mesh="shoulder_pitch_link_visual" material="shoulder_pitch_link_visual_material"/>
      <geom type="mesh" class="collision" pos="4.53819e-18 -0.0129132 7.89907e-19" quat="1 0 0 0" mesh="shoulder_pitch_link_collision" material="shoulder_pitch_link_collision_material"/>
      <body name="shoulder_roll_link" pos="0.019 -0.027 1.77841e-17" quat="0.5 -0.5 -0.5 0.5">
        <joint axis="0 0 1" name="shoulder_roll" type="hinge" range="-0.4363323129985806 1.5707963267948983"/>
        <inertial pos="-0.0118938 0.00123983 0.0185214" mass="0.110689" fullinertia="2.42151e-05 3.09134e-05 3.21504e-05 -2.25274e-07 3.92857e-08 -5.94432e-07"/>
        <geom type="mesh" class="visual" pos="-0.0118938 0.00123983 0.0185214" quat="0.5 0.5 0.5 -0.5" mesh="shoulder_roll_link_visual" material="shoulder_roll_link_visual_material"/>
        <geom type="mesh" class="collision" pos="-0.0118938 0.00123983 0.0185214" quat="0.5 0.5 0.5 -0.5" mesh="shoulder_roll_link_collision" material="shoulder_roll_link_collision_material"/>
        <body name="shoulder_gear_drive" pos="-0.024 0.019 0.019" quat="0.5 0.5 -0.5 0.5">
          <joint axis="0 0 1" name="shoulder_yaw_drive" type="hinge" range="-3.1415926535897922 3.141592653589794"/>
          <inertial pos="2.39005e-15 1.04535e-15 -0.00644196" mass="0.0032" fullinertia="1.53683e-07 1.53683e-07 2.31059e-07 -2.16335e-15 -1.20371e-35 0"/>
          <geom type="mesh" class="visual" pos="2.39005e-15 1.04777e-15 -0.00644196" quat="1.10167e-13 2.08256e-13 -5.05151e-14 1" mesh="shoulder_gear_drive_visual" material="shoulder_gear_drive_visual_material"/>
          <geom type="mesh" class="collision" pos="2.39005e-15 1.04777e-15 -0.00644196" quat="1.10167e-13 2.08256e-13 -5.05151e-14 1" mesh="shoulder_gear_drive_collision" material="shoulder_gear_drive_collision_material"/>
        </body>
        <body name="shoulder_yaw_link" pos="-3.58103e-10 0.026 0.019" quat="0.5 -0.5 -0.5 -0.5">
          <joint axis="0 0 1" name="shoulder_yaw_driven" type="hinge" range="-3.141592653589794 3.1415926535897922"/>
          <inertial pos="5.87796e-18 -2.3683e-16 0.0252377" mass="0.018004" fullinertia="7.79124e-06 1.16309e-05 5.15938e-06 -7.4881e-13 -2.86677e-20 -1.42396e-19"/>
          <geom type="mesh" class="visual" pos="5.87796e-18 -2.32453e-16 0.0252377" quat="2.09624e-13 -4.24072e-15 1 -3.3496e-13" mesh="shoulder_yaw_link_visual" material="shoulder_yaw_link_visual_material"/>
          <geom type="mesh" class="collision" pos="5.87796e-18 -2.32453e-16 0.0252377" quat="2.09624e-13 -4.24072e-15 1 -3.3496e-13" mesh="shoulder_yaw_link_collision" material="shoulder_yaw_link_collision_material"/>
          <body name="elbow_roll_link" pos="-0.019 3.01842e-16 0.0616" quat="0.5 -0.5 0.5 -0.5">
            <joint axis="0 0 1" name="elbow_roll" type="hinge" range="-2.268928027592609 1.919862177193782"/>
            <inertial pos="0.0118938 -0.00123983 0.0185214" mass="0.110689" fullinertia="2.42151e-05 3.09134e-05 3.21504e-05 -2.25274e-07 -3.92857e-08 5.94432e-07"/>
            <geom type="mesh" class="visual" pos="0.0118938 -0.00123983 0.0185214" quat="0.5 -0.5 0.5 0.5" mesh="elbow_roll_link_visual" material="elbow_roll_link_visual_material"/>
            <geom type="mesh" class="collision" pos="0.0118938 -0.00123983 0.0185214" quat="0.5 -0.5 0.5 0.5" mesh="elbow_roll_link_collision" material="elbow_roll_link_collision_material"/>
            <body name="elbow_gear_drive" pos="0.024 -0.019 0.019" quat="0.5 -0.5 0.5 0.5">
              <joint axis="0 0 1" name="elbow_yaw_drive" type="hinge" range="-3.1415926535897913 3.141592653589795"/>
              <inertial pos="2.38993e-15 1.03909e-15 -0.00644196" mass="0.0032" fullinertia="1.53683e-07 1.53683e-07 2.31059e-07 -2.16335e-15 -4.81482e-35 -3.00927e-36"/>
              <geom type="mesh" class="visual" pos="2.38993e-15 1.04083e-15 -0.00644196" quat="1 4.67472e-14 -8.32445e-13 -6.42184e-15" mesh="elbow_gear_drive_visual" material="elbow_gear_drive_visual_material"/>
              <geom type="mesh" class="collision" pos="2.38993e-15 1.04083e-15 -0.00644196" quat="1 4.67472e-14 -8.32445e-13 -6.42184e-15" mesh="elbow_gear_drive_collision" material="elbow_gear_drive_collision_material"/>
            </body>
            <body name="elbow_yaw_link" pos="3.58104e-10 -0.026 0.019" quat="0.5 0.5 0.5 -0.5">
              <joint axis="0 0 1" name="elbow_yaw_driven" type="hinge" range="-3.141592653589795 3.1415926535897913"/>
              <inertial pos="-1.17769e-12 -0.00218443 0.0302811" mass="0.0244684" fullinertia="2.23488e-05 1.23953e-05 1.19136e-05 2.6007e-13 2.46679e-15 1.40833e-06"/>
              <geom type="mesh" class="visual" pos="-1.17769e-12 -0.00218443 0.0302811" quat="4.69155e-14 -1 -6.39694e-15 8.32075e-13" mesh="elbow_yaw_link_visual" material="elbow_yaw_link_visual_material"/>
              <geom type="mesh" class="collision" pos="-1.17769e-12 -0.00218443 0.0302811" quat="4.69155e-14 -1 -6.39694e-15 8.32075e-13" mesh="elbow_yaw_link_collision" material="elbow_yaw_link_collision_material"/>
              <body name="wrist_pitch_link" pos="9.74938e-17 -0.0197 0.0576" quat="0.5 -0.5 -0.5 -0.5">
                <joint axis="0 0 1" name="wrist_pitch_driven" type="hinge" range="-2.0943951023931953 2.0943951023931953"/>
                <inertial pos="-0.0117155 -0.000458143 0.0227029" mass="0.115599" fullinertia="2.65503e-05 3.48077e-05 3.22022e-05 3.02182e-08 -2.46695e-07 5.44493e-07"/>
                <geom type="mesh" class="visual" pos="-0.0117155 -0.000458143 0.0227029" quat="0.5 -0.5 -0.5 0.5" mesh="wrist_pitch_link_visual" material="wrist_pitch_link_visual_material"/>
                <geom type="mesh" class="collision" pos="-0.0117155 -0.000458143 0.0227029" quat="0.5 -0.5 -0.5 0.5" mesh="wrist_pitch_link_collision" material="wrist_pitch_link_collision_material"/>
                <body name="wrist_gear_drive" pos="-0.024 1.52463e-10 0.004" quat="3.99572e-16 -0.707107 0.707107 -2.04348e-16">
                  <joint axis="0 0 1" name="wrist_pitch_drive" type="hinge" range="-2.0943951023931953 2.0943951023931953"/>
                  <inertial pos="3.05102e-15 6.47634e-17 0.00480965" mass="0.0032" fullinertia="1.40976e-07 1.40976e-07 2.41078e-07 1.61116e-15 -2.58828e-39 -3.24156e-36"/>
                  <geom type="mesh" class="visual" pos="3.05102e-15 5.55112e-17 0.00480965" quat="4.55291e-13 4.46196e-13 0.707107 0.707107" mesh="wrist_gear_drive_visual" material="wrist_gear_drive_visual_material"/>
                  <geom type="mesh" class="collision" pos="3.05102e-15 5.55112e-17 0.00480965" quat="4.55291e-13 4.46196e-13 0.707107 0.707107" mesh="wrist_gear_drive_collision" material="wrist_gear_drive_collision_material"/>
                </body>
                <body name="leader_hand" pos="3.58075e-10 -0.019 0.023" quat="0.5 0.5 0.5 -0.5">
                  <joint axis="0 0 1" name="wrist_roll" type="hinge" range="-1.570796326794408 1.570796326795385"/>
                  <inertial pos="2.41105e-08 0.0406582 -0.0186609" mass="0.017" fullinertia="9.19142e-06 6.63273e-06 3.79456e-06 1.39884e-12 -9.47511e-12 4.48222e-08"/>
                  <geom type="mesh" class="visual" pos="2.41105e-08 0.0406582 -0.0186609" quat="0.5 0.5 0.5 -0.5" mesh="leader_hand_visual" material="leader_hand_visual_material"/>
                  <geom type="mesh" class="collision" pos="2.41105e-08 0.0406582 -0.0186609" quat="0.5 0.5 0.5 -0.5" mesh="leader_hand_collision" material="leader_hand_collision_material"/>
                </body>
              </body>
            </body>
          </body>
        </body>
      </body>
    </body>
  </worldbody>
  <asset>
    <mesh file="merged/elbow_gear_drive_visual.stl"/>
    <mesh file="merged/shoulder_pitch_link_visual.stl"/>
    <mesh file="merged/shoulder_gear_drive_visual.stl"/>
    <mesh file="merged/shoulder_gear_drive_collision.stl"/>
    <mesh file="merged/shoulder_roll_link_visual.stl"/>
    <mesh file="merged/wrist_gear_drive_visual.stl"/>
    <mesh file="merged/shoulder_roll_link_collision.stl"/>
    <mesh file="merged/leader_hand_collision.stl"/>
    <mesh file="merged/elbow_gear_drive_collision.stl"/>
    <mesh file="merged/elbow_yaw_link_collision.stl"/>
    <mesh file="merged/shoulder_yaw_link_collision.stl"/>
    <mesh file="merged/leader_hand_visual.stl"/>
    <mesh file="merged/wrist_pitch_link_visual.stl"/>
    <mesh file="merged/wrist_pitch_link_collision.stl"/>
    <mesh file="merged/elbow_roll_link_collision.stl"/>
    <mesh file="merged/shoulder_pitch_link_collision.stl"/>
    <mesh file="merged/elbow_yaw_link_visual.stl"/>
    <mesh file="merged/wrist_gear_drive_collision.stl"/>
    <mesh file="merged/shoulder_yaw_link_visual.stl"/>
    <mesh file="merged/elbow_roll_link_visual.stl"/>
    <material name="shoulder_pitch_link_visual_material" rgba="0.615686 0.811765 0.929412 1"/>
    <material name="shoulder_pitch_link_collision_material" rgba="0.615686 0.811765 0.929412 1"/>
    <material name="shoulder_roll_link_visual_material" rgba="0.76356 0.870485 0.928205 1"/>
    <material name="shoulder_roll_link_collision_material" rgba="0.76356 0.870485 0.928205 1"/>
    <material name="shoulder_gear_drive_visual_material" rgba="0.615686 0.811765 0.929412 1"/>
    <material name="shoulder_gear_drive_collision_material" rgba="0.615686 0.811765 0.929412 1"/>
    <material name="shoulder_yaw_link_visual_material" rgba="0.57829 0.731061 0.843405 1"/>
    <material name="shoulder_yaw_link_collision_material" rgba="0.57829 0.731061 0.843405 1"/>
    <material name="elbow_roll_link_visual_material" rgba="0.76356 0.870485 0.928205 1"/>
    <material name="elbow_roll_link_collision_material" rgba="0.76356 0.870485 0.928205 1"/>
    <material name="elbow_gear_drive_visual_material" rgba="0.615686 0.811765 0.929412 1"/>
    <material name="elbow_gear_drive_collision_material" rgba="0.615686 0.811765 0.929412 1"/>
    <material name="elbow_yaw_link_visual_material" rgba="0.560653 0.693 0.802843 1"/>
    <material name="elbow_yaw_link_collision_material" rgba="0.560653 0.693 0.802843 1"/>
    <material name="wrist_pitch_link_visual_material" rgba="0.772103 0.856582 0.890498 1"/>
    <material name="wrist_pitch_link_collision_material" rgba="0.772103 0.856582 0.890498 1"/>
    <material name="wrist_gear_drive_visual_material" rgba="0.615686 0.811765 0.929412 1"/>
    <material name="wrist_gear_drive_collision_material" rgba="0.615686 0.811765 0.929412 1"/>
    <material name="leader_hand_visual_material" rgba="0.615686 0.811765 0.929412 1"/>
    <material name="leader_hand_collision_material" rgba="0.615686 0.811765 0.929412 1"/>
  </asset>
  <actuator>
    <position class="right_arm_leader" name="shoulder_roll" joint="shoulder_roll" inheritrange="1"/>
    <position class="right_arm_leader" name="shoulder_yaw_drive" joint="shoulder_yaw_drive" inheritrange="1"/>
    <position class="right_arm_leader" name="elbow_roll" joint="elbow_roll" inheritrange="1"/>
    <position class="right_arm_leader" name="elbow_yaw_drive" joint="elbow_yaw_drive" inheritrange="1"/>
    <position class="right_arm_leader" name="wrist_pitch_drive" joint="wrist_pitch_drive" inheritrange="1"/>
    <position class="right_arm_leader" name="wrist_roll" joint="wrist_roll" inheritrange="1"/>
  </actuator>
  <equality>
    <joint joint1="shoulder_yaw_driven" joint2="shoulder_yaw_drive" polycoef="0 -1.0 0 0 0"/>
    <joint joint1="elbow_yaw_driven" joint2="elbow_yaw_drive" polycoef="0 -1.0 0 0 0"/>
    <joint joint1="wrist_pitch_driven" joint2="wrist_pitch_drive" polycoef="0 -1.0 0 0 0"/>
  </equality>
</mujoco>